Workbook
Name cfgAcademyClass: 'Settings'!$C$6
Name cfgStartDate: 'Settings'!$C$7
Name cfgEndDate: 'Settings'!$C$8
Name cfgTotalScheduledMinutes: 'Settings'!$C$9
Name cfgPassingScore: 'Settings'!$C$10
Name cfgThresholdScore: 'Settings'!$C$11
Name cfgRetakeRecordedCap: 'Settings'!$C$12
Name cfgThresholdAfterExam: 'Settings'!$C$13
Name cfgRetestClassDays: 'Settings'!$C$14
Name cfgMemoDueClassDays: 'Settings'!$C$15
Name cfgWeightMajor: 'Settings'!$C$16
Name cfgWeightMinor: 'Settings'!$C$17
Name cfgWeightSpelling: 'Settings'!$C$18
Name cfgWeightFinal: 'Settings'!$C$19
Name cfgSpellInterventionAvg: 'Settings'!$C$20
Name cfgMakeupAdvisoryMin: 'Settings'!$C$21
Name cfgMakeupCriticalMin: 'Settings'!$C$22
Name cfgPTCapSessions: 'Settings'!$C$23
Name cfgAttendanceAdvisoryPct: 'Settings'!$C$24
Name cfgAttendanceCriticalPct: 'Settings'!$C$25
Name cfgHomeAgency: 'Settings'!$C$26
Name cfgCurrentExamNum: 'Settings'!$C$27
Name cfgCurrentSpellingNum: 'Settings'!$C$28
Name cfgWritingDueTime: 'Settings'!$C$29
Name cfgPTFinalMinPoints: 'Settings'!$C$30
Name cfgFlagConsecFails: 'Settings'!$C$31
Name cfgFlagGradeDrop: 'Settings'!$C$32
Name cfgFlagCategoryMargin: 'Settings'!$C$33
Name cfgFlagAttendancePct: 'Settings'!$C$34
Name cfgFlagOpenIncidents: 'Settings'!$C$35
Name cfgFlagOverdueWriting: 'Settings'!$C$36
Name cfgWeightsTotal: 'Settings'!$C$37
Name nrPTTierPts: 'Settings'!$D$43:$H$43
Name nrPTBands: 'Settings'!$D$44:$H$48
Name nrPTBandEvents: 'Settings'!$B$44:$B$48
Name lstYesNo: 'Lists'!$B$6:$B$7
Name lstCadetStatus: 'Lists'!$C$6:$C$9
Name lstExamType: 'Lists'!$D$6:$D$8
Name lstAttendanceEvent: 'Lists'!$E$6:$E$14
Name lstReason: 'Lists'!$F$6:$F$12
Name lstDocumentation: 'Lists'!$G$6:$G$8
Name lstExcused: 'Lists'!$H$6:$H$7
Name lstMakeupType: 'Lists'!$I$6:$I$7
Name lstScoringMode: 'Lists'!$J$6:$J$7
Name lstSkillResult: 'Lists'!$K$6:$K$8
Name lstIncidentDirection: 'Lists'!$L$6:$L$8
Name lstSeverity: 'Lists'!$M$6:$M$10
Name lstResolution: 'Lists'!$N$6:$N$9
Name lstAssignmentType: 'Lists'!$O$6:$O$10
Name lstSubmission: 'Lists'!$P$6:$P$9
Name lstAttemptNum: 'Lists'!$Q$6:$Q$10
Name lstExamAttemptNum: 'Lists'!$R$6:$R$7
Name lstIssuetype: 'Lists'!$S$6:$S$12
Name lstCounselingType: 'Lists'!$T$6:$T$13
Name lstMedicalStatus: 'Lists'!$U$6:$U$9
Name lstPtSession: 'Lists'!$V$6:$V$8
Name lstAward: 'Lists'!$W$6:$W$9
Name lstInstructorType: 'Lists'!$X$6:$X$9
Name lstMaterialsStatus: 'Lists'!$Y$6:$Y$9
Name lstRequirementSource: 'Lists'!$Z$6:$Z$7

Sheet Dashboard
B5: =cfgAcademyClass&" — Dashboard" | H5: ="As of "&TEXT(TODAY(),"mm/dd/yyyy") | J5: =HYPERLINK("#InputGuide!B5","Data Entry Guide →")
B7: Academy start | D7: Final Exam date | F7: State Exam date | H7: Graduation / end | J7: Active cadets
B8: =TEXT(cfgStartDate,"mm/dd/yyyy") | D8: =_xlfn.LET(_xlpm.d,_xlfn.MAXIFS(nrSCH_Date,nrSCH_Act,"Final Test"),IF(_xlpm.d=0,"(not on schedule)",TEXT(_xlpm.d,"mm/dd/yyyy"))) | F8: =_xlfn.LET(_xlpm.d,_xlfn.MAXIFS(nrSCH_Date,nrSCH_Act,"State Test"),IF(_xlpm.d=0,"(not on schedule)",TEXT(_xlpm.d,"mm/dd/yyyy"))) | H8: =_xlfn.LET(_xlpm.d,_xlfn.MAXIFS(nrSCH_Date,nrSCH_Act,"Graduation"),IF(_xlpm.d=0,TEXT(cfgEndDate,"mm/dd/yyyy"),TEXT(_xlpm.d,"mm/dd/yyyy"))) | J8: =SUMPRODUCT((nrCadetStatus="Active")*1)
B10: Today
B11: =IF(COUNTIF(nrDL_Date,TODAY())=0,"DailyLog: no entry for today yet","DailyLog: entered ✓") | H11: =IFERROR("Training Day #"&_xlfn.XLOOKUP(TODAY(),nrCDdate,nrCDnum)&" (Week "&_xlfn.XLOOKUP(TODAY(),nrCDdate,nrCDweek)&")","(not a class day)")
B13: ="TODAY — "&UPPER(TEXT(TODAY(),"dddd, mmmm d"))&IFERROR(" — TRAINING DAY #"&_xlfn.XLOOKUP(TODAY(),nrCDdate,nrCDnum)&", WEEK "&_xlfn.XLOOKUP(TODAY(),nrCDdate,nrCDweek),"")
B14: =IFERROR(_xlfn.TAKE(_xlfn._xlws.FILTER(_xlfn.HSTACK(TEXT(nrSCH_Start,"h:mm AM/PM"),TEXT(nrSCH_End,"h:mm AM/PM"),nrSCH_Act,nrSCH_Instr,nrSCH_Loc),(nrSCH_Date<>"")*(nrSCH_Date=TODAY()),"No class scheduled today"),9),"⚠ LIST UNAVAILABLE - a reference in this panel is broken; do NOT read it as 'nothing to report'")
B23: Separated / total enrolled | D23: Class current avg | F23: Graduation eligible | H23: Flagged cadets | J23: Retests overdue / late / undated
B24: =SUMPRODUCT((nrCadetStatus="Separated")*1)&" / "&SUMPRODUCT((nrCadetStatus<>"")*1) | D24: =IFERROR(ROUND(AVERAGEIF(nrCadetStatus,"Active",nrGRcurrent),1),"—") | F24: =SUMPRODUCT((nrCadetStatus="Active")*(nrCKgradElig="Yes")) | H24: =SUMPRODUCT((nrCadetStatus="Active")*(nrFLcount>0)) | J24: =COUNTIF(nrES_RetStat,"OVERDUE")+COUNTIF(nrES_RetStat,"CHECK DATE")+COUNTIF(nrES_RetStat,"LATE RETEST*")+COUNTIF(nrES_RetStat,"RETEST UNDATED")+COUNTIF(nrES_RetStat,"RETEST DATE UNCHECKED")
B26: Spelling interventions | D26: Makeup owed (cadets) | F26: Delivered hours | H26: Audit checks failing | J26: Days to graduation | L26: Cert copies to collect
B27: =COUNTIF(nrSpellFlag,"INTERVENTION") | D27: =SUMPRODUCT((nrCadetStatus="Active")*(nrATTmakeupOK="No")) | F27: =ROUND(N(nrCHtotalDelivered),0)&" / "&cfgRequiredHours | H27: =SUMPRODUCT((nrAUDstatus<>"OK")*(nrAUDstatus<>"")) | J27: =MAX(0,cfgEndDate-TODAY()) | L27: =SUMPRODUCT((nrCadetStatus="Active")*(nrCERTmissing<>""))
B29: Watch list — highest flag counts first (full list on WatchList)
B30: =IFERROR(_xlfn.TAKE(_xlfn.SORTBY(_xlfn._xlws.FILTER(_xlfn.HSTACK(rngCadetNames,nrCadetAgency,nrFLcount,nrFLreasons),(nrFLcount>0)*(nrCadetStatus="Active"),"No flags — clear"),_xlfn._xlws.FILTER(nrFLcount,(nrFLcount>0)*(nrCadetStatus="Active"),"No flags — clear"),-1),11),"⚠ LIST UNAVAILABLE - a reference in this panel is broken; do NOT read it as 'nothing to report'")
B41: Certification reminders — copies to collect from cadets (Certifications sheet)
B42: =IFERROR(_xlfn.TAKE(_xlfn._xlws.FILTER(_xlfn.HSTACK(rngCadetNames,nrCadetAgency,nrCERTmissing),(nrCERTmissing<>"")*(nrCadetStatus="Active"),"All certification copies collected"),9),"⚠ LIST UNAVAILABLE - a reference in this panel is broken; do NOT read it as 'nothing to report'")
B51: Open missed-time events — not yet made up (Attendance ↔ Makeup by EventID)
B52: =IFERROR(_xlfn.TAKE(_xlfn.SORTBY(_xlfn._xlws.FILTER(_xlfn.HSTACK(nrAT_ID,Attendance!$D$6:$D$805,TEXT(nrAT_Date,"mm/dd"),Attendance!$G$6:$G$805,Attendance!$H$6:$H$805,nrAT_Balance),(nrAT_Cleared="OPEN"),"All missed time cleared"),_xlfn._xlws.FILTER(nrAT_Date,(nrAT_Cleared="OPEN"),"All missed time cleared"),-1),9),"⚠ LIST UNAVAILABLE - a reference in this panel is broken; do NOT read it as 'nothing to report'")
B61: Outstanding memos (pending / overdue)
B62: =IFERROR(_xlfn.TAKE(_xlfn.SORTBY(_xlfn._xlws.FILTER(_xlfn.HSTACK(Memos!$B$6:$B$305,nrME_Cadet,TEXT(nrME_Assigned,"mm/dd"),nrME_Ref,nrME_Subject,TEXT(nrME_Due,"mm/dd"),nrME_Status),(nrME_Cadet<>"")*(nrME_Received=""),"No memos outstanding"),_xlfn._xlws.FILTER(nrME_Due,(nrME_Cadet<>"")*(nrME_Received=""),"No memos outstanding"),1),8),"⚠ LIST UNAVAILABLE - a reference in this panel is broken; do NOT read it as 'nothing to report'")
B70: Class average by exam
B86: Spelling class average by test

Sheet StartHere
B1: =HYPERLINK("#Dashboard!B5","◄ Dashboard")
B4: Workbook map: CREAM boxes are yours to type (your entries show in blue), PALE BLUE = calculated, sys* sheets are the locked engine.
B5: Step | C5: What to do
B6: 1. Settings | C6: Set academy class label, start/end dates, weights, caps and flag thresholds. Blue cells are yours.
B7: 2. Lists / Agencies / Instructors | C7: Confirm dropdown lists, agency contacts and the instructor roster (PID, certs, SME letters).
B8: 3. ChapterMaster & Schedule | C8: Confirm chapter hours, then enter the class schedule (date, times, chapter, instructor). Delivered hours reconcile automatically.
B9: 4. ExamPlan / WritingMaster / SpellingMaster | C9: Pick this academy's exams; writing due dates compute from the schedule.
B10: 5. Cadets | C10: Enter the roster (PID, names, agency). Everything keys off PID.
B11: 6. Daily operation | C11: Log exam scores, spelling, attendance exceptions, makeup, skills, writing, incidents, counseling, PT and medical as they happen.
B12: 7. Watch the Dashboard / WatchList | C12: Flags, retest deadlines and blocking issues surface automatically.
B13: 8. Print Center | C13: Sign-in sheets, evals, spelling tests, writing handouts, transcripts and rosters — one place.
B14: 9. Agency emails | C14: EmailPreview + buttons draft per-agency Outlook emails for review. Never auto-sent.
B15: 10. New academy | C15: Save-As, then use the New Academy reset button. See the Coordinator Guide in docs/.

Sheet InputGuide
B1: =HYPERLINK("#Dashboard!B5","◄ Dashboard")
B4: Only pages that take input are listed — gray sys* tabs are the locked calculation engine; green tabs are outputs. Cream boxes are yours to type (what you type shows in blue); pale blue cells calculate.
B5: Go to… | C5: What you enter there
B6: Getting set up
B7: =HYPERLINK("#Settings!B6","Settings") | C7: Academy label, start/end dates, grading weights, caps, retest window, flag thresholds, PT points rubric (yellow block).
B8: =HYPERLINK("#Lists!B6","Lists") | C8: Dropdown choices used across the workbook — add items here.
B9: =HYPERLINK("#Agencies!B6","Agencies") | C9: Sending agencies: codes, contacts, email addresses.
B10: =HYPERLINK("#Instructors!B6","Instructors") | C10: Roster with TCOLE PID, certs, SME letters, bio-on-file status. 'On Schedule?' shows who actually teaches — every co-teacher needs documentation.
B11: =HYPERLINK("#InstructorBanks!B6","InstructorBanks") | C11: Per-topic banks: the certified pool (kept between academies) and who you picked to teach THIS academy — those picks become the Schedule's instructor dropdown for that topic.
B12: =HYPERLINK("#ChapterMaster!B6","ChapterMaster") | C12: Chapter hours + the per-chapter TCOLE training-file record (lesson plan, bio, sign-ins, assessment, grade sheet, eval, special requirements).
B13: =HYPERLINK("#Control!B6","Control") | C13: Extra closure dates (holidays compute automatically).
B14: =HYPERLINK("#Schedule!B6","Schedule") | C14: The class schedule: one row per time block — date, times, chapter/activity, instructor. Drives hours, due dates, sign-ins.
B15: =HYPERLINK("#ExamPlan!B6","ExamPlan") | C15: Which exams this academy uses, their sequence and linked chapters.
B16: =HYPERLINK("#ExamMaster!B6","ExamMaster") | C16: The exam library (edit names/types/defaults).
B17: =HYPERLINK("#SkillsMaster!B6","SkillsMaster") | C17: Attempt limits and scoring mode per skill category.
B18: =HYPERLINK("#SpellingMaster!B6","SpellingMaster") | C18: The 12 spelling word lists (printable via Print Center).
B19: =HYPERLINK("#WritingMaster!B6","WritingMaster") | C19: The 40 assignments: prompts, linked chapters, date overrides.
B20: Daily operation
B21: =HYPERLINK("#Cadets!B6","Cadets") | C21: The roster: PID, names, agency, status, enroll/separation.
B22: =HYPERLINK("#ExamScores!B6","ExamScores") | C22: One row per exam attempt: cadet, exam, attempt #, raw score, date. Retest deadlines compute.
B23: =HYPERLINK("#Spelling!B6","Spelling") | C23: Spelling test scores per cadet per test.
B24: =HYPERLINK("#Attendance!B6","Attendance") | C24: Exception log: missed/modified time in minutes (or PT sessions), reason, documentation, excused.
B25: =HYPERLINK("#Makeup!B6","Makeup") | C25: Makeup credit: minutes/sessions, documentation, holds.
B26: =HYPERLINK("#Skills!B6","Skills") | C26: Skills attempts: category, result, score, firearms course of fire.
B27: =HYPERLINK("#SkillsCheck!B6","SkillsCheck") | C27: One Pass/Fail per skills training per cadet — your call, not the attempt log's. Marking any skill Fail blocks graduation and names that skill in Blocking Issues. Blank is not a failure, but it is counted under 'Not Assessed'.
B28: =HYPERLINK("#Writing!B6","Writing") | C28: Type X when an assignment is received (auto-capitalizes).
B29: =HYPERLINK("#Incidents!B6","Incidents") | C29: Positive/negative incidents with severity and resolution.
B30: =HYPERLINK("#Counseling!B6","Counseling") | C30: Every intervention: tutoring, counseling, agency notification, performance plans. 'Agency Notified?' = Yes puts it in the next email digest.
B31: =HYPERLINK("#Memos!B6","Memos") | C31: Deficiency memos: assign, link to the I/A/C record, due auto-computes, mark received. 'Report to Agency?' is your call.
B32: =HYPERLINK("#DailyLog!B6","DailyLog") | C32: One row per training day — the digital daily report. Counters compute; mark when the leader's signed report is scanned.
B33: =HYPERLINK("#PT!B6","PT") | C33: Baseline and final raw values per event; final points once the rubric arrives.
B34: =HYPERLINK("#Medical!B6","Medical") | C34: Injuries, restrictions, clearances and expirations.
B35: =HYPERLINK("#Certifications!B6","Certifications") | C35: Per-cadet TIM/SFST/TCIC/CPR/ALERRT/ICS completion dates and certificate copies collected.
B36: =HYPERLINK("#StateExam!B6","StateExam") | C36: TCOLE licensing exam attempts and results (3 max).
B37: =HYPERLINK("#DismissalLog!B6","DismissalLog") | C37: Formal reviews: trigger, decision, approvals.
B38: =HYPERLINK("#AdvisoryBoard!B6","AdvisoryBoard") | C38: Governance: this academy's alignment record (policy version, minutes reviewed, workbook aligned) + the running board-meeting list with minutes folder locations. The Startup Review button fills it.
B39: End of academy / as needed
B40: =HYPERLINK("#Audit!B6","Audit") | C40: Program-requirement checklist answers + per-cadet enrollment documents grid.
B41: =HYPERLINK("#EmailPreview!B6","EmailPreview") | C41: Pick an agency to preview its email; the button builds Outlook drafts.
B42: =HYPERLINK("#sysAwards!B6","sysAwards") | C42: Award override cells — your pick always wins.
...

Sheet PrintCenter
B1: =HYPERLINK("#Dashboard!B5","◄ Dashboard")
B5: Print Center
B7: What | C7: How | D7: Sheet | E7: Macro (button)
B8: Daily report & roster (one day) | C8: Set the date on SignIn; blank date prints a generic form the leader dates by hand | D8: SignIn | E8: btnPrintSignIn
B9: Daily report & roster (week) | C9: Prints the next 5 class days, each pre-filled with its own date, day # and schedule | D9: SignIn | E9: btnPrintSignInWeek
B10: Academy book (all days) | C10: Every class day's form in one run — the class leader's bound book for the whole academy (print to PDF for the print shop) | D10: SignIn | E10: btnPrintSignInAcademy
B11: Course critique stack | C11: Set chapter on EvalSheet; prints one per active cadet | D11: EvalSheet | E11: btnPrintEvals
B12: Spelling test / key | C12: Set test # and mode on SpellingPrint | D12: SpellingPrint | E12: btnPrintSpelling
B13: Writing handout (week) | C13: Set week # on WritingHandout | D13: WritingHandout | E13: btnPrintWriting
B14: Cadet profile | C14: Set cadet on CadetProfile | D14: CadetProfile | E14: btnPrintProfile
B15: Transcript | C15: Set cadet on Transcript (button can run all cadets) | D15: Transcript | E15: btnPrintTranscript
B16: Class ranking | C16: Prints as-is | D16: Ranking | E16: btnPrintRanking
B17: Graduation checklist | C17: Prints as-is | D17: GradChecklist | E17: btnPrintGradCheck
B18: Audit packet | C18: Program checks + enrollment docs | D18: Audit | E18: btnPrintAudit
... B22: Schedule | C22: Full schedule listing | D22: Schedule | E22: btnPrintSchedule
B24: Buttons are added by the BPOC VBA install — run tools/Install-BPOC-VBA.ps1 (see docs/BPOC-Coordinator-Guide.md, 'Rebuilding from source'). Each button prints its sheet's defined print area to the default printer; Ctrl+P on the sheet does the same thing manually.

Sheet Cadets
B1: =HYPERLINK("#Dashboard!B5","◄ Dashboard")
B4: PID never changes once set — every other sheet keys off it. Capacity 50 cadets. A red PID (or red Cadet Name) means two rows share it: fix it immediately, both cadets' records are being merged.
B5: PID | C5: Last Name | D5: First Name | E5: MI | F5: Cadet Name | G5: AgencyID | H5: Agency Name | I5: Status | J5: Sort | K5: Enroll Date | L5: Separation Date | M5: Separation Reason
F6: =IF($B6="","",$C6&", "&$D6&IF($E6="",""," "&$E6&".")) | H6: =IF($G6="","",IFERROR(INDEX(rngAgencyNames,MATCH($G6,rngAgencyIDs,0)),"?")) | J6: =IF($B6="","",ROW()-5)
F7: =IF($B7="","",$C7&", "&$D7&IF($E7="",""," "&$E7&".")) | H7: =IF($G7="","",IFERROR(INDEX(rngAgencyNames,MATCH($G7,rngAgencyIDs,0)),"?")) | J7: =IF($B7="","",ROW()-5)
F8: =IF($B8="","",$C8&", "&$D8&IF($E8="",""," "&$E8&".")) | H8: =IF($G8="","",IFERROR(INDEX(rngAgencyNames,MATCH($G8,rngAgencyIDs,0)),"?")) | J8: =IF($B8="","",ROW()-5)
F9: =IF($B9="","",$C9&", "&$D9&IF($E9="",""," "&$E9&".")) | H9: =IF($G9="","",IFERROR(INDEX(rngAgencyNames,MATCH($G9,rngAgencyIDs,0)),"?")) | J9: =IF($B9="","",ROW()-5)
F10: =IF($B10="","",$C10&", "&$D10&IF($E10="",""," "&$E10&".")) | H10: =IF($G10="","",IFERROR(INDEX(rngAgencyNames,MATCH($G10,rngAgencyIDs,0)),"?")) | J10: =IF($B10="","",ROW()-5)
F11: =IF($B11="","",$C11&", "&$D11&IF($E11="",""," "&$E11&".")) | H11: =IF($G11="","",IFERROR(INDEX(rngAgencyNames,MATCH($G11,rngAgencyIDs,0)),"?")) | J11: =IF($B11="","",ROW()-5)
F12: =IF($B12="","",$C12&", "&$D12&IF($E12="",""," "&$E12&".")) | H12: =IF($G12="","",IFERROR(INDEX(rngAgencyNames,MATCH($G12,rngAgencyIDs,0)),"?")) | J12: =IF($B12="","",ROW()-5)
F13: =IF($B13="","",$C13&", "&$D13&IF($E13="",""," "&$E13&".")) | H13: =IF($G13="","",IFERROR(INDEX(rngAgencyNames,MATCH($G13,rngAgencyIDs,0)),"?")) | J13: =IF($B13="","",ROW()-5)
F14: =IF($B14="","",$C14&", "&$D14&IF($E14="",""," "&$E14&".")) | H14: =IF($G14="","",IFERROR(INDEX(rngAgencyNames,MATCH($G14,rngAgencyIDs,0)),"?")) | J14: =IF($B14="","",ROW()-5)
F15: =IF($B15="","",$C15&", "&$D15&IF($E15="",""," "&$E15&".")) | H15: =IF($G15="","",IFERROR(INDEX(rngAgencyNames,MATCH($G15,rngAgencyIDs,0)),"?")) | J15: =IF($B15="","",ROW()-5)
F16: =IF($B16="","",$C16&", "&$D16&IF($E16="",""," "&$E16&".")) | H16: =IF($G16="","",IFERROR(INDEX(rngAgencyNames,MATCH($G16,rngAgencyIDs,0)),"?")) | J16: =IF($B16="","",ROW()-5)
F17: =IF($B17="","",$C17&", "&$D17&IF($E17="",""," "&$E17&".")) | H17: =IF($G17="","",IFERROR(INDEX(rngAgencyNames,MATCH($G17,rngAgencyIDs,0)),"?")) | J17: =IF($B17="","",ROW()-5)
... F55: =IF($B55="","",$C55&", "&$D55&IF($E55="",""," "&$E55&".")) | H55: =IF($G55="","",IFERROR(INDEX(rngAgencyNames,MATCH($G55,rngAgencyIDs,0)),"?")) | J55: =IF($B55="","",ROW()-5)

Sheet ExamScores
B1: =HYPERLINK("#Dashboard!B5","◄ Dashboard")
B4: One row per attempt. Attempt 2 of a failed exam records at the 70 cap when passed (policy 300.5). Retest Due By = 5 class days after the failed attempt's date (a date that is not a class day rolls to the next one). Watch Row Check: a score that is not a number, a duplicate RecordID, an attempt 2 with no attempt 1 on file, or an attempt 2 logged against a first attempt that already PASSED each distort the category average. ABSENCE (last column): Unexcused = key Raw Score 0 as well - the zero is the record and it starts the retest clock; Excused = leave Raw Score blank, the first attempt is simply taken later and Retest Status reads EXCUSED - 1st attempt pending until the score is keyed on this same row.
B5: RecordID | C5: Cadet Name | D5: PID | E5: Agency | F5: ExamCode | G5: Exam Name | H5: Type | I5: Seq | J5: Passing | K5: Attempt # | L5: Raw Score | M5: Recorded | N5: AttemptPass | O5: Pass? | P5: FinalAttempt? | Q5: RetakeReq? | R5: DismissReview? | S5: Date | T5: Retest Due By | U5: Retest Status | V5: Entered By | W5: Notes | X5: Row Check | Y5: Absence
B6: =IF($C6="","",$D6&"-"&$F6&"-"&$K6) | D6: =IF($C6="","",IFERROR(INDEX(rngCadetPIDs,MATCH($C6,rngCadetNames,0)),"?")) | E6: =IF($D6="","",IFERROR(INDEX(nrCadetAgency,MATCH($D6,rngCadetPIDs,0)),"")) | G6: =IF($F6="","",IFERROR(INDEX(rngEPname,MATCH($F6,rngEPcode,0)),"?")) | H6: =IF($F6="","",IFERROR(INDEX(rngEPtype,MATCH($F6,rngEPcode,0)),"?")) | I6: =IF($F6="","",IFERROR(INDEX(rngEPseq,MATCH($F6,rngEPcode,0)),"")) | J6: =IF($F6="","",IFERROR(INDEX(rngEPpass,MATCH($F6,rngEPcode,0)),cfgPassingScore)) | M6: =IF($C6="","",IF($L6="","",IF(NOT(ISNUMBER($L6)),$L6,IF(N($K6)>2,"",IF($K6=1,IF(COUNTIFS(nrES_PID,$D6,nrES_Code,$F6,nrES_Att,2,nrES_Raw,">=0")>0,"",$L6),IF($L6>=$J6,MAX($J6,cfgRetakeRecordedCap),IF(COUNTIFS(nrES_PID,$D6,nrES_Code,$F6,nrES_Att,1)=0,$L6,SUMIFS(nrES_Raw,nrES_PID,$D6,nrES_Code,$F6,nrES_Att,1)))))))) | N6: =IF($C6="","",IF($L6="","",IF(NOT(ISNUMBER($L6)),"(not a score)",IF($L6>=$J6,"Yes","No")))) | O6: =IF($C6="","",IF($M6="","",IF(NOT(ISNUMBER($M6)),"(not a score)",IF($M6>=$J6,"Yes","No")))) | P6: =IF($C6="","",IF($K6="","",IF(N($K6)>2,"No",IF(COUNTIFS(nrES_PID,$D6,nrES_Code,$F6,nrES_Att,">"&$K6,nrES_Att,"<=2",nrES_Raw,">=0")=0,"Yes","No")))) | Q6: =IF($C6="","",IF($L6="","",IF(AND($K6=1,ISNUMBER($L6),$L6<$J6,COUNTIFS(nrES_PID,$D6,nrES_Code,$F6,nrES_Att,2,nrES_Raw,">=0")=0),"Yes","No"))) | R6: =IF($C6="","",IF($L6="","",IF(AND(N($K6)>=2,ISNUMBER($L6),$L6<$J6),"Yes","No"))) | T6: =IF(OR($C6="",$L6="",$K6<>1,NOT(ISNUMBER($L6)),$L6>=$J6),"",IF($S6="","(enter date)",_xlfn.LET(_xlpm.dn,_xlfn.XLOOKUP($S6,nrCDdate,nrCDnum,"",1),IF(_xlpm.dn="","(after last class day)",_xlfn.LET(_xlpm.dd,_xlfn.XLOOKUP(_xlpm.dn+cfgRetestClassDays,nrCDnum,nrCDdate,""),_xlpm.ok,_xlfn.XLOOKUP(_xlpm.dn+cfgRetestClassDays,nrCDnum,nrCDinsession,"No"),IF(OR(_xlpm.dd="",_xlpm.ok<>"Yes"),"(after last class day)",_xlpm.dd)))))) | U6: =IF($C6="","",IF(AND($Y6="Excused",$L6="",N($K6)<=1),"EXCUSED - 1st attempt pending",IF(OR($L6="",$K6<>1,NOT(ISNUMBER($L6)),$L6>=$J6),"",IF(COUNTIFS(nrES_PID,$D6,nrES_Code,$F6,nrES_Att,2,nrES_Raw,">=0")>0,IF(IFERROR(_xlfn.MINIFS(nrES_Date,nrES_PID,$D6,nrES_Code,$F6,nrES_Att,2,nrES_Raw,">=0",nrES_Date,">0"),0)=0,"RETEST UNDATED",IF(NOT(ISNUMBER($T6)),"RETEST DATE UNCHECKED",IF(_xlfn.MINIFS(nrES_Date,nrES_PID,$D6,nrES_Code,$F6,nrES_Att,2,nrES_Raw,">=0",nrES_Date,">0")>$T6,"LATE RETEST "&TEXT(_xlfn.MINIFS(nrES_Date,nrES_PID,$D6,nrES_Code,$F6,nrES_Att,2,nrES_Raw,">=0",nrES_Date,">0"),"mm/dd")&" (due "&TEXT($T6,"mm/dd")&")","Retested"))),IF(NOT(ISNUMBER($T6)),"CHECK DATE",IF(TODAY()>$T6,"OVERDUE","Due "&TEXT($T6,"mm/dd"))))))) | X6: =IF($C6="","",IF(AND($L6<>"",NOT(ISNUMBER($L6))),"RAW SCORE NOT A NUMBER",IF(AND(ISNUMBER($L6),OR($L6<0,$L6>100)),"RAW SCORE OUT OF RANGE",IF(AND($Y6="Unexcused",OR($L6="",NOT(ISNUMBER($L6)),$L6<>0)),"UNEXCUSED ABSENCE MUST RECORD 0",IF(COUNTIF(nrES_RecID,$B6)>1,"DUPLICATE RECORD",IF(N($K6)>2,"ATTEMPT 3+ NOT ALLOWED - policy 300.5 permits one retest per exam; this row records nothing",IF(AND($K6=2,COUNTIFS(nrES_PID,$D6,nrES_Code,$F6,nrES_Att,1)=0),"ATTEMPT 2 WITHOUT ATTEMPT 1",IF(AND($K6=2,$L6=""),"RETEST ROW HAS NO SCORE",IF(AND($H6="Final",$L6<>"",IFERROR(INDEX(nrCKfinalExamElig,MATCH($D6,rngCadetPIDs,0)),"")="No"),"FINAL EXAM AFTER FAILED FINAL PT (500.1.H)",IF(AND($K6=2,ISNUMBER($L6),COUNTIFS(nrES_PID,$D6,nrES_Code,$F6,nrES_Att,1)>0,SUMIFS(nrES_Raw,nrES_PID,$D6,nrES_Code,$F6,nrES_Att,1)>=$J6),"RETEST AFTER A PASSING FIRST ATTEMPT","OK"))))))))))
B7: =IF($C7="","",$D7&"-"&$F7&"-"&$K7) | D7: =IF($C7="","",IFERROR(INDEX(rngCadetPIDs,MATCH($C7,rngCadetNames,0)),"?")) | E7: =IF($D7="","",IFERROR(INDEX(nrCadetAgency,MATCH($D7,rngCadetPIDs,0)),"")) | G7: =IF($F7="","",IFERROR(INDEX(rngEPname,MATCH($F7,rngEPcode,0)),"?")) | H7: =IF($F7="","",IFERROR(INDEX(rngEPtype,MATCH($F7,rngEPcode,0)),"?")) | I7: =IF($F7="","",IFERROR(INDEX(rngEPseq,MATCH($F7,rngEPcode,0)),"")) | J7: =IF($F7="","",IFERROR(INDEX(rngEPpass,MATCH($F7,rngEPcode,0)),cfgPassingScore)) | M7: =IF($C7="","",IF($L7="","",IF(NOT(ISNUMBER($L7)),$L7,IF(N($K7)>2,"",IF($K7=1,IF(COUNTIFS(nrES_PID,$D7,nrES_Code,$F7,nrES_Att,2,nrES_Raw,">=0")>0,"",$L7),IF($L7>=$J7,MAX($J7,cfgRetakeRecordedCap),IF(COUNTIFS(nrES_PID,$D7,nrES_Code,$F7,nrES_Att,1)=0,$L7,SUMIFS(nrES_Raw,nrES_PID,$D7,nrES_Code,$F7,nrES_Att,1)))))))) | N7: =IF($C7="","",IF($L7="","",IF(NOT(ISNUMBER($L7)),"(not a score)",IF($L7>=$J7,"Yes","No")))) | O7: =IF($C7="","",IF($M7="","",IF(NOT(ISNUMBER($M7)),"(not a score)",IF($M7>=$J7,"Yes","No")))) | P7: =IF($C7="","",IF($K7="","",IF(N($K7)>2,"No",IF(COUNTIFS(nrES_PID,$D7,nrES_Code,$F7,nrES_Att,">"&$K7,nrES_Att,"<=2",nrES_Raw,">=0")=0,"Yes","No")))) | Q7: =IF($C7="","",IF($L7="","",IF(AND($K7=1,ISNUMBER($L7),$L7<$J7,COUNTIFS(nrES_PID,$D7,nrES_Code,$F7,nrES_Att,2,nrES_Raw,">=0")=0),"Yes","No"))) | R7: =IF($C7="","",IF($L7="","",IF(AND(N($K7)>=2,ISNUMBER($L7),$L7<$J7),"Yes","No"))) | T7: =IF(OR($C7="",$L7="",$K7<>1,NOT(ISNUMBER($L7)),$L7>=$J7),"",IF($S7="","(enter date)",_xlfn.LET(_xlpm.dn,_xlfn.XLOOKUP($S7,nrCDdate,nrCDnum,"",1),IF(_xlpm.dn="","(after last class day)",_xlfn.LET(_xlpm.dd,_xlfn.XLOOKUP(_xlpm.dn+cfgRetestClassDays,nrCDnum,nrCDdate,""),_xlpm.ok,_xlfn.XLOOKUP(_xlpm.dn+cfgRetestClassDays,nrCDnum,nrCDinsession,"No"),IF(OR(_xlpm.dd="",_xlpm.ok<>"Yes"),"(after last class day)",_xlpm.dd)))))) | U7: =IF($C7="","",IF(AND($Y7="Excused",$L7="",N($K7)<=1),"EXCUSED - 1st attempt pending",IF(OR($L7="",$K7<>1,NOT(ISNUMBER($L7)),$L7>=$J7),"",IF(COUNTIFS(nrES_PID,$D7,nrES_Code,$F7,nrES_Att,2,nrES_Raw,">=0")>0,IF(IFERROR(_xlfn.MINIFS(nrES_Date,nrES_PID,$D7,nrES_Code,$F7,nrES_Att,2,nrES_Raw,">=0",nrES_Date,">0"),0)=0,"RETEST UNDATED",IF(NOT(ISNUMBER($T7)),"RETEST DATE UNCHECKED",IF(_xlfn.MINIFS(nrES_Date,nrES_PID,$D7,nrES_Code,$F7,nrES_Att,2,nrES_Raw,">=0",nrES_Date,">0")>$T7,"LATE RETEST "&TEXT(_xlfn.MINIFS(nrES_Date,nrES_PID,$D7,nrES_Code,$F7,nrES_Att,2,nrES_Raw,">=0",nrES_Date,">0"),"mm/dd")&" (due "&TEXT($T7,"mm/dd")&")","Retested"))),IF(NOT(ISNUMBER($T7)),"CHECK DATE",IF(TODAY()>$T7,"OVERDUE","Due "&TEXT($T7,"mm/dd"))))))) | X7: =IF($C7="","",IF(AND($L7<>"",NOT(ISNUMBER($L7))),"RAW SCORE NOT A NUMBER",IF(AND(ISNUMBER($L7),OR($L7<0,$L7>100)),"RAW SCORE OUT OF RANGE",IF(AND($Y7="Unexcused",OR($L7="",NOT(ISNUMBER($L7)),$L7<>0)),"UNEXCUSED ABSENCE MUST RECORD 0",IF(COUNTIF(nrES_RecID,$B7)>1,"DUPLICATE RECORD",IF(N($K7)>2,"ATTEMPT 3+ NOT ALLOWED - policy 300.5 permits one retest per exam; this row records nothing",IF(AND($K7=2,COUNTIFS(nrES_PID,$D7,nrES_Code,$F7,nrES_Att,1)=0),"ATTEMPT 2 WITHOUT ATTEMPT 1",IF(AND($K7=2,$L7=""),"RETEST ROW HAS NO SCORE",IF(AND($H7="Final",$L7<>"",IFERROR(INDEX(nrCKfinalExamElig,MATCH($D7,rngCadetPIDs,0)),"")="No"),"FINAL EXAM AFTER FAILED FINAL PT (500.1.H)",IF(AND($K7=2,ISNUMBER($L7),COUNTIFS(nrES_PID,$D7,nrES_Code,$F7,nrES_Att,1)>0,SUMIFS(nrES_Raw,nrES_PID,$D7,nrES_Code,$F7,nrES_Att,1)>=$J7),"RETEST AFTER A PASSING FIRST ATTEMPT","OK"))))))))))
B8: =IF($C8="","",$D8&"-"&$F8&"-"&$K8) | D8: =IF($C8="","",IFERROR(INDEX(rngCadetPIDs,MATCH($C8,rngCadetNames,0)),"?")) | E8: =IF($D8="","",IFERROR(INDEX(nrCadetAgency,MATCH($D8,rngCadetPIDs,0)),"")) | G8: =IF($F8="","",IFERROR(INDEX(rngEPname,MATCH($F8,rngEPcode,0)),"?")) | H8: =IF($F8="","",IFERROR(INDEX(rngEPtype,MATCH($F8,rngEPcode,0)),"?")) | I8: =IF($F8="","",IFERROR(INDEX(rngEPseq,MATCH($F8,rngEPcode,0)),"")) | J8: =IF($F8="","",IFERROR(INDEX(rngEPpass,MATCH($F8,rngEPcode,0)),cfgPassingScore)) | M8: =IF($C8="","",IF($L8="","",IF(NOT(ISNUMBER($L8)),$L8,IF(N($K8)>2,"",IF($K8=1,IF(COUNTIFS(nrES_PID,$D8,nrES_Code,$F8,nrES_Att,2,nrES_Raw,">=0")>0,"",$L8),IF($L8>=$J8,MAX($J8,cfgRetakeRecordedCap),IF(COUNTIFS(nrES_PID,$D8,nrES_Code,$F8,nrES_Att,1)=0,$L8,SUMIFS(nrES_Raw,nrES_PID,$D8,nrES_Code,$F8,nrES_Att,1)))))))) | N8: =IF($C8="","",IF($L8="","",IF(NOT(ISNUMBER($L8)),"(not a score)",IF($L8>=$J8,"Yes","No")))) | O8: =IF($C8="","",IF($M8="","",IF(NOT(ISNUMBER($M8)),"(not a score)",IF($M8>=$J8,"Yes","No")))) | P8: =IF($C8="","",IF($K8="","",IF(N($K8)>2,"No",IF(COUNTIFS(nrES_PID,$D8,nrES_Code,$F8,nrES_Att,">"&$K8,nrES_Att,"<=2",nrES_Raw,">=0")=0,"Yes","No")))) | Q8: =IF($C8="","",IF($L8="","",IF(AND($K8=1,ISNUMBER($L8),$L8<$J8,COUNTIFS(nrES_PID,$D8,nrES_Code,$F8,nrES_Att,2,nrES_Raw,">=0")=0),"Yes","No"))) | R8: =IF($C8="","",IF($L8="","",IF(AND(N($K8)>=2,ISNUMBER($L8),$L8<$J8),"Yes","No"))) | T8: =IF(OR($C8="",$L8="",$K8<>1,NOT(ISNUMBER($L8)),$L8>=$J8),"",IF($S8="","(enter date)",_xlfn.LET(_xlpm.dn,_xlfn.XLOOKUP($S8,nrCDdate,nrCDnum,"",1),IF(_xlpm.dn="","(after last class day)",_xlfn.LET(_xlpm.dd,_xlfn.XLOOKUP(_xlpm.dn+cfgRetestClassDays,nrCDnum,nrCDdate,""),_xlpm.ok,_xlfn.XLOOKUP(_xlpm.dn+cfgRetestClassDays,nrCDnum,nrCDinsession,"No"),IF(OR(_xlpm.dd="",_xlpm.ok<>"Yes"),"(after last class day)",_xlpm.dd)))))) | U8: =IF($C8="","",IF(AND($Y8="Excused",$L8="",N($K8)<=1),"EXCUSED - 1st attempt pending",IF(OR($L8="",$K8<>1,NOT(ISNUMBER($L8)),$L8>=$J8),"",IF(COUNTIFS(nrES_PID,$D8,nrES_Code,$F8,nrES_Att,2,nrES_Raw,">=0")>0,IF(IFERROR(_xlfn.MINIFS(nrES_Date,nrES_PID,$D8,nrES_Code,$F8,nrES_Att,2,nrES_Raw,">=0",nrES_Date,">0"),0)=0,"RETEST UNDATED",IF(NOT(ISNUMBER($T8)),"RETEST DATE UNCHECKED",IF(_xlfn.MINIFS(nrES_Date,nrES_PID,$D8,nrES_Code,$F8,nrES_Att,2,nrES_Raw,">=0",nrES_Date,">0")>$T8,"LATE RETEST "&TEXT(_xlfn.MINIFS(nrES_Date,nrES_PID,$D8,nrES_Code,$F8,nrES_Att,2,nrES_Raw,">=0",nrES_Date,">0"),"mm/dd")&" (due "&TEXT($T8,"mm/dd")&")","Retested"))),IF(NOT(ISNUMBER($T8)),"CHECK DATE",IF(TODAY()>$T8,"OVERDUE","Due "&TEXT($T8,"mm/dd"))))))) | X8: =IF($C8="","",IF(AND($L8<>"",NOT(ISNUMBER($L8))),"RAW SCORE NOT A NUMBER",IF(AND(ISNUMBER($L8),OR($L8<0,$L8>100)),"RAW SCORE OUT OF RANGE",IF(AND($Y8="Unexcused",OR($L8="",NOT(ISNUMBER($L8)),$L8<>0)),"UNEXCUSED ABSENCE MUST RECORD 0",IF(COUNTIF(nrES_RecID,$B8)>1,"DUPLICATE RECORD",IF(N($K8)>2,"ATTEMPT 3+ NOT ALLOWED - policy 300.5 permits one retest per exam; this row records nothing",IF(AND($K8=2,COUNTIFS(nrES_PID,$D8,nrES_Code,$F8,nrES_Att,1)=0),"ATTEMPT 2 WITHOUT ATTEMPT 1",IF(AND($K8=2,$L8=""),"RETEST ROW HAS NO SCORE",IF(AND($H8="Final",$L8<>"",IFERROR(INDEX(nrCKfinalExamElig,MATCH($D8,rngCadetPIDs,0)),"")="No"),"FINAL EXAM AFTER FAILED FINAL PT (500.1.H)",IF(AND($K8=2,ISNUMBER($L8),COUNTIFS(nrES_PID,$D8,nrES_Code,$F8,nrES_Att,1)>0,SUMIFS(nrES_Raw,nrES_PID,$D8,nrES_Code,$F8,nrES_Att,1)>=$J8),"RETEST AFTER A PASSING FIRST ATTEMPT","OK"))))))))))
B9: =IF($C9="","",$D9&"-"&$F9&"-"&$K9) | D9: =IF($C9="","",IFERROR(INDEX(rngCadetPIDs,MATCH($C9,rngCadetNames,0)),"?")) | E9: =IF($D9="","",IFERROR(INDEX(nrCadetAgency,MATCH($D9,rngCadetPIDs,0)),"")) | G9: =IF($F9="","",IFERROR(INDEX(rngEPname,MATCH($F9,rngEPcode,0)),"?")) | H9: =IF($F9="","",IFERROR(INDEX(rngEPtype,MATCH($F9,rngEPcode,0)),"?")) | I9: =IF($F9="","",IFERROR(INDEX(rngEPseq,MATCH($F9,rngEPcode,0)),"")) | J9: =IF($F9="","",IFERROR(INDEX(rngEPpass,MATCH($F9,rngEPcode,0)),cfgPassingScore)) | M9: =IF($C9="","",IF($L9="","",IF(NOT(ISNUMBER($L9)),$L9,IF(N($K9)>2,"",IF($K9=1,IF(COUNTIFS(nrES_PID,$D9,nrES_Code,$F9,nrES_Att,2,nrES_Raw,">=0")>0,"",$L9),IF($L9>=$J9,MAX($J9,cfgRetakeRecordedCap),IF(COUNTIFS(nrES_PID,$D9,nrES_Code,$F9,nrES_Att,1)=0,$L9,SUMIFS(nrES_Raw,nrES_PID,$D9,nrES_Code,$F9,nrES_Att,1)))))))) | N9: =IF($C9="","",IF($L9="","",IF(NOT(ISNUMBER($L9)),"(not a score)",IF($L9>=$J9,"Yes","No")))) | O9: =IF($C9="","",IF($M9="","",IF(NOT(ISNUMBER($M9)),"(not a score)",IF($M9>=$J9,"Yes","No")))) | P9: =IF($C9="","",IF($K9="","",IF(N($K9)>2,"No",IF(COUNTIFS(nrES_PID,$D9,nrES_Code,$F9,nrES_Att,">"&$K9,nrES_Att,"<=2",nrES_Raw,">=0")=0,"Yes","No")))) | Q9: =IF($C9="","",IF($L9="","",IF(AND($K9=1,ISNUMBER($L9),$L9<$J9,COUNTIFS(nrES_PID,$D9,nrES_Code,$F9,nrES_Att,2,nrES_Raw,">=0")=0),"Yes","No"))) | R9: =IF($C9="","",IF($L9="","",IF(AND(N($K9)>=2,ISNUMBER($L9),$L9<$J9),"Yes","No"))) | T9: =IF(OR($C9="",$L9="",$K9<>1,NOT(ISNUMBER($L9)),$L9>=$J9),"",IF($S9="","(enter date)",_xlfn.LET(_xlpm.dn,_xlfn.XLOOKUP($S9,nrCDdate,nrCDnum,"",1),IF(_xlpm.dn="","(after last class day)",_xlfn.LET(_xlpm.dd,_xlfn.XLOOKUP(_xlpm.dn+cfgRetestClassDays,nrCDnum,nrCDdate,""),_xlpm.ok,_xlfn.XLOOKUP(_xlpm.dn+cfgRetestClassDays,nrCDnum,nrCDinsession,"No"),IF(OR(_xlpm.dd="",_xlpm.ok<>"Yes"),"(after last class day)",_xlpm.dd)))))) | U9: =IF($C9="","",IF(AND($Y9="Excused",$L9="",N($K9)<=1),"EXCUSED - 1st attempt pending",IF(OR($L9="",$K9<>1,NOT(ISNUMBER($L9)),$L9>=$J9),"",IF(COUNTIFS(nrES_PID,$D9,nrES_Code,$F9,nrES_Att,2,nrES_Raw,">=0")>0,IF(IFERROR(_xlfn.MINIFS(nrES_Date,nrES_PID,$D9,nrES_Code,$F9,nrES_Att,2,nrES_Raw,">=0",nrES_Date,">0"),0)=0,"RETEST UNDATED",IF(NOT(ISNUMBER($T9)),"RETEST DATE UNCHECKED",IF(_xlfn.MINIFS(nrES_Date,nrES_PID,$D9,nrES_Code,$F9,nrES_Att,2,nrES_Raw,">=0",nrES_Date,">0")>$T9,"LATE RETEST "&TEXT(_xlfn.MINIFS(nrES_Date,nrES_PID,$D9,nrES_Code,$F9,nrES_Att,2,nrES_Raw,">=0",nrES_Date,">0"),"mm/dd")&" (due "&TEXT($T9,"mm/dd")&")","Retested"))),IF(NOT(ISNUMBER($T9)),"CHECK DATE",IF(TODAY()>$T9,"OVERDUE","Due "&TEXT($T9,"mm/dd"))))))) | X9: =IF($C9="","",IF(AND($L9<>"",NOT(ISNUMBER($L9))),"RAW SCORE NOT A NUMBER",IF(AND(ISNUMBER($L9),OR($L9<0,$L9>100)),"RAW SCORE OUT OF RANGE",IF(AND($Y9="Unexcused",OR($L9="",NOT(ISNUMBER($L9)),$L9<>0)),"UNEXCUSED ABSENCE MUST RECORD 0",IF(COUNTIF(nrES_RecID,$B9)>1,"DUPLICATE RECORD",IF(N($K9)>2,"ATTEMPT 3+ NOT ALLOWED - policy 300.5 permits one retest per exam; this row records nothing",IF(AND($K9=2,COUNTIFS(nrES_PID,$D9,nrES_Code,$F9,nrES_Att,1)=0),"ATTEMPT 2 WITHOUT ATTEMPT 1",IF(AND($K9=2,$L9=""),"RETEST ROW HAS NO SCORE",IF(AND($H9="Final",$L9<>"",IFERROR(INDEX(nrCKfinalExamElig,MATCH($D9,rngCadetPIDs,0)),"")="No"),"FINAL EXAM AFTER FAILED FINAL PT (500.1.H)",IF(AND($K9=2,ISNUMBER($L9),COUNTIFS(nrES_PID,$D9,nrES_Code,$F9,nrES_Att,1)>0,SUMIFS(nrES_Raw,nrES_PID,$D9,nrES_Code,$F9,nrES_Att,1)>=$J9),"RETEST AFTER A PASSING FIRST ATTEMPT","OK"))))))))))
B10: =IF($C10="","",$D10&"-"&$F10&"-"&$K10) | D10: =IF($C10="","",IFERROR(INDEX(rngCadetPIDs,MATCH($C10,rngCadetNames,0)),"?")) | E10: =IF($D10="","",IFERROR(INDEX(nrCadetAgency,MATCH($D10,rngCadetPIDs,0)),"")) | G10: =IF($F10="","",IFERROR(INDEX(rngEPname,MATCH($F10,rngEPcode,0)),"?")) | H10: =IF($F10="","",IFERROR(INDEX(rngEPtype,MATCH($F10,rngEPcode,0)),"?")) | I10: =IF($F10="","",IFERROR(INDEX(rngEPseq,MATCH($F10,rngEPcode,0)),"")) | J10: =IF($F10="","",IFERROR(INDEX(rngEPpass,MATCH($F10,rngEPcode,0)),cfgPassingScore)) | M10: =IF($C10="","",IF($L10="","",IF(NOT(ISNUMBER($L10)),$L10,IF(N($K10)>2,"",IF($K10=1,IF(COUNTIFS(nrES_PID,$D10,nrES_Code,$F10,nrES_Att,2,nrES_Raw,">=0")>0,"",$L10),IF($L10>=$J10,MAX($J10,cfgRetakeRecordedCap),IF(COUNTIFS(nrES_PID,$D10,nrES_Code,$F10,nrES_Att,1)=0,$L10,SUMIFS(nrES_Raw,nrES_PID,$D10,nrES_Code,$F10,nrES_Att,1)))))))) | N10: =IF($C10="","",IF($L10="","",IF(NOT(ISNUMBER($L10)),"(not a score)",IF($L10>=$J10,"Yes","No")))) | O10: =IF($C10="","",IF($M10="","",IF(NOT(ISNUMBER($M10)),"(not a score)",IF($M10>=$J10,"Yes","No")))) | P10: =IF($C10="","",IF($K10="","",IF(N($K10)>2,"No",IF(COUNTIFS(nrES_PID,$D10,nrES_Code,$F10,nrES_Att,">"&$K10,nrES_Att,"<=2",nrES_Raw,">=0")=0,"Yes","No")))) | Q10: =IF($C10="","",IF($L10="","",IF(AND($K10=1,ISNUMBER($L10),$L10<$J10,COUNTIFS(nrES_PID,$D10,nrES_Code,$F10,nrES_Att,2,nrES_Raw,">=0")=0),"Yes","No"))) | R10: =IF($C10="","",IF($L10="","",IF(AND(N($K10)>=2,ISNUMBER($L10),$L10<$J10),"Yes","No"))) | T10: =IF(OR($C10="",$L10="",$K10<>1,NOT(ISNUMBER($L10)),$L10>=$J10),"",IF($S10="","(enter date)",_xlfn.LET(_xlpm.dn,_xlfn.XLOOKUP($S10,nrCDdate,nrCDnum,"",1),IF(_xlpm.dn="","(after last class day)",_xlfn.LET(_xlpm.dd,_xlfn.XLOOKUP(_xlpm.dn+cfgRetestClassDays,nrCDnum,nrCDdate,""),_xlpm.ok,_xlfn.XLOOKUP(_xlpm.dn+cfgRetestClassDays,nrCDnum,nrCDinsession,"No"),IF(OR(_xlpm.dd="",_xlpm.ok<>"Yes"),"(after last class day)",_xlpm.dd)))))) | U10: =IF($C10="","",IF(AND($Y10="Excused",$L10="",N($K10)<=1),"EXCUSED - 1st attempt pending",IF(OR($L10="",$K10<>1,NOT(ISNUMBER($L10)),$L10>=$J10),"",IF(COUNTIFS(nrES_PID,$D10,nrES_Code,$F10,nrES_Att,2,nrES_Raw,">=0")>0,IF(IFERROR(_xlfn.MINIFS(nrES_Date,nrES_PID,$D10,nrES_Code,$F10,nrES_Att,2,nrES_Raw,">=0",nrES_Date,">0"),0)=0,"RETEST UNDATED",IF(NOT(ISNUMBER($T10)),"RETEST DATE UNCHECKED",IF(_xlfn.MINIFS(nrES_Date,nrES_PID,$D10,nrES_Code,$F10,nrES_Att,2,nrES_Raw,">=0",nrES_Date,">0")>$T10,"LATE RETEST "&TEXT(_xlfn.MINIFS(nrES_Date,nrES_PID,$D10,nrES_Code,$F10,nrES_Att,2,nrES_Raw,">=0",nrES_Date,">0"),"mm/dd")&" (due "&TEXT($T10,"mm/dd")&")","Retested"))),IF(NOT(ISNUMBER($T10)),"CHECK DATE",IF(TODAY()>$T10,"OVERDUE","Due "&TEXT($T10,"mm/dd"))))))) | X10: =IF($C10="","",IF(AND($L10<>"",NOT(ISNUMBER($L10))),"RAW SCORE NOT A NUMBER",IF(AND(ISNUMBER($L10),OR($L10<0,$L10>100)),"RAW SCORE OUT OF RANGE",IF(AND($Y10="Unexcused",OR($L10="",NOT(ISNUMBER($L10)),$L10<>0)),"UNEXCUSED ABSENCE MUST RECORD 0",IF(COUNTIF(nrES_RecID,$B10)>1,"DUPLICATE RECORD",IF(N($K10)>2,"ATTEMPT 3+ NOT ALLOWED - policy 300.5 permits one retest per exam; this row records nothing",IF(AND($K10=2,COUNTIFS(nrES_PID,$D10,nrES_Code,$F10,nrES_Att,1)=0),"ATTEMPT 2 WITHOUT ATTEMPT 1",IF(AND($K10=2,$L10=""),"RETEST ROW HAS NO SCORE",IF(AND($H10="Final",$L10<>"",IFERROR(INDEX(nrCKfinalExamElig,MATCH($D10,rngCadetPIDs,0)),"")="No"),"FINAL EXAM AFTER FAILED FINAL PT (500.1.H)",IF(AND($K10=2,ISNUMBER($L10),COUNTIFS(nrES_PID,$D10,nrES_Code,$F10,nrES_Att,1)>0,SUMIFS(nrES_Raw,nrES_PID,$D10,nrES_Code,$F10,nrES_Att,1)>=$J10),"RETEST AFTER A PASSING FIRST ATTEMPT","OK"))))))))))
B11: =IF($C11="","",$D11&"-"&$F11&"-"&$K11) | D11: =IF($C11="","",IFERROR(INDEX(rngCadetPIDs,MATCH($C11,rngCadetNames,0)),"?")) | E11: =IF($D11="","",IFERROR(INDEX(nrCadetAgency,MATCH($D11,rngCadetPIDs,0)),"")) | G11: =IF($F11="","",IFERROR(INDEX(rngEPname,MATCH($F11,rngEPcode,0)),"?")) | H11: =IF($F11="","",IFERROR(INDEX(rngEPtype,MATCH($F11,rngEPcode,0)),"?")) | I11: =IF($F11="","",IFERROR(INDEX(rngEPseq,MATCH($F11,rngEPcode,0)),"")) | J11: =IF($F11="","",IFERROR(INDEX(rngEPpass,MATCH($F11,rngEPcode,0)),cfgPassingScore)) | M11: =IF($C11="","",IF($L11="","",IF(NOT(ISNUMBER($L11)),$L11,IF(N($K11)>2,"",IF($K11=1,IF(COUNTIFS(nrES_PID,$D11,nrES_Code,$F11,nrES_Att,2,nrES_Raw,">=0")>0,"",$L11),IF($L11>=$J11,MAX($J11,cfgRetakeRecordedCap),IF(COUNTIFS(nrES_PID,$D11,nrES_Code,$F11,nrES_Att,1)=0,$L11,SUMIFS(nrES_Raw,nrES_PID,$D11,nrES_Code,$F11,nrES_Att,1)))))))) | N11: =IF($C11="","",IF($L11="","",IF(NOT(ISNUMBER($L11)),"(not a score)",IF($L11>=$J11,"Yes","No")))) | O11: =IF($C11="","",IF($M11="","",IF(NOT(ISNUMBER($M11)),"(not a score)",IF($M11>=$J11,"Yes","No")))) | P11: =IF($C11="","",IF($K11="","",IF(N($K11)>2,"No",IF(COUNTIFS(nrES_PID,$D11,nrES_Code,$F11,nrES_Att,">"&$K11,nrES_Att,"<=2",nrES_Raw,">=0")=0,"Yes","No")))) | Q11: =IF($C11="","",IF($L11="","",IF(AND($K11=1,ISNUMBER($L11),$L11<$J11,COUNTIFS(nrES_PID,$D11,nrES_Code,$F11,nrES_Att,2,nrES_Raw,">=0")=0),"Yes","No"))) | R11: =IF($C11="","",IF($L11="","",IF(AND(N($K11)>=2,ISNUMBER($L11),$L11<$J11),"Yes","No"))) | T11: =IF(OR($C11="",$L11="",$K11<>1,NOT(ISNUMBER($L11)),$L11>=$J11),"",IF($S11="","(enter date)",_xlfn.LET(_xlpm.dn,_xlfn.XLOOKUP($S11,nrCDdate,nrCDnum,"",1),IF(_xlpm.dn="","(after last class day)",_xlfn.LET(_xlpm.dd,_xlfn.XLOOKUP(_xlpm.dn+cfgRetestClassDays,nrCDnum,nrCDdate,""),_xlpm.ok,_xlfn.XLOOKUP(_xlpm.dn+cfgRetestClassDays,nrCDnum,nrCDinsession,"No"),IF(OR(_xlpm.dd="",_xlpm.ok<>"Yes"),"(after last class day)",_xlpm.dd)))))) | U11: =IF($C11="","",IF(AND($Y11="Excused",$L11="",N($K11)<=1),"EXCUSED - 1st attempt pending",IF(OR($L11="",$K11<>1,NOT(ISNUMBER($L11)),$L11>=$J11),"",IF(COUNTIFS(nrES_PID,$D11,nrES_Code,$F11,nrES_Att,2,nrES_Raw,">=0")>0,IF(IFERROR(_xlfn.MINIFS(nrES_Date,nrES_PID,$D11,nrES_Code,$F11,nrES_Att,2,nrES_Raw,">=0",nrES_Date,">0"),0)=0,"RETEST UNDATED",IF(NOT(ISNUMBER($T11)),"RETEST DATE UNCHECKED",IF(_xlfn.MINIFS(nrES_Date,nrES_PID,$D11,nrES_Code,$F11,nrES_Att,2,nrES_Raw,">=0",nrES_Date,">0")>$T11,"LATE RETEST "&TEXT(_xlfn.MINIFS(nrES_Date,nrES_PID,$D11,nrES_Code,$F11,nrES_Att,2,nrES_Raw,">=0",nrES_Date,">0"),"mm/dd")&" (due "&TEXT($T11,"mm/dd")&")","Retested"))),IF(NOT(ISNUMBER($T11)),"CHECK DATE",IF(TODAY()>$T11,"OVERDUE","Due "&TEXT($T11,"mm/dd"))))))) | X11: =IF($C11="","",IF(AND($L11<>"",NOT(ISNUMBER($L11))),"RAW SCORE NOT A NUMBER",IF(AND(ISNUMBER($L11),OR($L11<0,$L11>100)),"RAW SCORE OUT OF RANGE",IF(AND($Y11="Unexcused",OR($L11="",NOT(ISNUMBER($L11)),$L11<>0)),"UNEXCUSED ABSENCE MUST RECORD 0",IF(COUNTIF(nrES_RecID,$B11)>1,"DUPLICATE RECORD",IF(N($K11)>2,"ATTEMPT 3+ NOT ALLOWED - policy 300.5 permits one retest per exam; this row records nothing",IF(AND($K11=2,COUNTIFS(nrES_PID,$D11,nrES_Code,$F11,nrES_Att,1)=0),"ATTEMPT 2 WITHOUT ATTEMPT 1",IF(AND($K11=2,$L11=""),"RETEST ROW HAS NO SCORE",IF(AND($H11="Final",$L11<>"",IFERROR(INDEX(nrCKfinalExamElig,MATCH($D11,rngCadetPIDs,0)),"")="No"),"FINAL EXAM AFTER FAILED FINAL PT (500.1.H)",IF(AND($K11=2,ISNUMBER($L11),COUNTIFS(nrES_PID,$D11,nrES_Code,$F11,nrES_Att,1)>0,SUMIFS(nrES_Raw,nrES_PID,$D11,nrES_Code,$F11,nrES_Att,1)>=$J11),"RETEST AFTER A PASSING FIRST ATTEMPT","OK"))))))))))
B12: =IF($C12="","",$D12&"-"&$F12&"-"&$K12) | D12: =IF($C12="","",IFERROR(INDEX(rngCadetPIDs,MATCH($C12,rngCadetNames,0)),"?")) | E12: =IF($D12="","",IFERROR(INDEX(nrCadetAgency,MATCH($D12,rngCadetPIDs,0)),"")) | G12: =IF($F12="","",IFERROR(INDEX(rngEPname,MATCH($F12,rngEPcode,0)),"?")) | H12: =IF($F12="","",IFERROR(INDEX(rngEPtype,MATCH($F12,rngEPcode,0)),"?")) | I12: =IF($F12="","",IFERROR(INDEX(rngEPseq,MATCH($F12,rngEPcode,0)),"")) | J12: =IF($F12="","",IFERROR(INDEX(rngEPpass,MATCH($F12,rngEPcode,0)),cfgPassingScore)) | M12: =IF($C12="","",IF($L12="","",IF(NOT(ISNUMBER($L12)),$L12,IF(N($K12)>2,"",IF($K12=1,IF(COUNTIFS(nrES_PID,$D12,nrES_Code,$F12,nrES_Att,2,nrES_Raw,">=0")>0,"",$L12),IF($L12>=$J12,MAX($J12,cfgRetakeRecordedCap),IF(COUNTIFS(nrES_PID,$D12,nrES_Code,$F12,nrES_Att,1)=0,$L12,SUMIFS(nrES_Raw,nrES_PID,$D12,nrES_Code,$F12,nrES_Att,1)))))))) | N12: =IF($C12="","",IF($L12="","",IF(NOT(ISNUMBER($L12)),"(not a score)",IF($L12>=$J12,"Yes","No")))) | O12: =IF($C12="","",IF($M12="","",IF(NOT(ISNUMBER($M12)),"(not a score)",IF($M12>=$J12,"Yes","No")))) | P12: =IF($C12="","",IF($K12="","",IF(N($K12)>2,"No",IF(COUNTIFS(nrES_PID,$D12,nrES_Code,$F12,nrES_Att,">"&$K12,nrES_Att,"<=2",nrES_Raw,">=0")=0,"Yes","No")))) | Q12: =IF($C12="","",IF($L12="","",IF(AND($K12=1,ISNUMBER($L12),$L12<$J12,COUNTIFS(nrES_PID,$D12,nrES_Code,$F12,nrES_Att,2,nrES_Raw,">=0")=0),"Yes","No"))) | R12: =IF($C12="","",IF($L12="","",IF(AND(N($K12)>=2,ISNUMBER($L12),$L12<$J12),"Yes","No"))) | T12: =IF(OR($C12="",$L12="",$K12<>1,NOT(ISNUMBER($L12)),$L12>=$J12),"",IF($S12="","(enter date)",_xlfn.LET(_xlpm.dn,_xlfn.XLOOKUP($S12,nrCDdate,nrCDnum,"",1),IF(_xlpm.dn="","(after last class day)",_xlfn.LET(_xlpm.dd,_xlfn.XLOOKUP(_xlpm.dn+cfgRetestClassDays,nrCDnum,nrCDdate,""),_xlpm.ok,_xlfn.XLOOKUP(_xlpm.dn+cfgRetestClassDays,nrCDnum,nrCDinsession,"No"),IF(OR(_xlpm.dd="",_xlpm.ok<>"Yes"),"(after last class day)",_xlpm.dd)))))) | U12: =IF($C12="","",IF(AND($Y12="Excused",$L12="",N($K12)<=1),"EXCUSED - 1st attempt pending",IF(OR($L12="",$K12<>1,NOT(ISNUMBER($L12)),$L12>=$J12),"",IF(COUNTIFS(nrES_PID,$D12,nrES_Code,$F12,nrES_Att,2,nrES_Raw,">=0")>0,IF(IFERROR(_xlfn.MINIFS(nrES_Date,nrES_PID,$D12,nrES_Code,$F12,nrES_Att,2,nrES_Raw,">=0",nrES_Date,">0"),0)=0,"RETEST UNDATED",IF(NOT(ISNUMBER($T12)),"RETEST DATE UNCHECKED",IF(_xlfn.MINIFS(nrES_Date,nrES_PID,$D12,nrES_Code,$F12,nrES_Att,2,nrES_Raw,">=0",nrES_Date,">0")>$T12,"LATE RETEST "&TEXT(_xlfn.MINIFS(nrES_Date,nrES_PID,$D12,nrES_Code,$F12,nrES_Att,2,nrES_Raw,">=0",nrES_Date,">0"),"mm/dd")&" (due "&TEXT($T12,"mm/dd")&")","Retested"))),IF(NOT(ISNUMBER($T12)),"CHECK DATE",IF(TODAY()>$T12,"OVERDUE","Due "&TEXT($T12,"mm/dd"))))))) | X12: =IF($C12="","",IF(AND($L12<>"",NOT(ISNUMBER($L12))),"RAW SCORE NOT A NUMBER",IF(AND(ISNUMBER($L12),OR($L12<0,$L12>100)),"RAW SCORE OUT OF RANGE",IF(AND($Y12="Unexcused",OR($L12="",NOT(ISNUMBER($L12)),$L12<>0)),"UNEXCUSED ABSENCE MUST RECORD 0",IF(COUNTIF(nrES_RecID,$B12)>1,"DUPLICATE RECORD",IF(N($K12)>2,"ATTEMPT 3+ NOT ALLOWED - policy 300.5 permits one retest per exam; this row records nothing",IF(AND($K12=2,COUNTIFS(nrES_PID,$D12,nrES_Code,$F12,nrES_Att,1)=0),"ATTEMPT 2 WITHOUT ATTEMPT 1",IF(AND($K12=2,$L12=""),"RETEST ROW HAS NO SCORE",IF(AND($H12="Final",$L12<>"",IFERROR(INDEX(nrCKfinalExamElig,MATCH($D12,rngCadetPIDs,0)),"")="No"),"FINAL EXAM AFTER FAILED FINAL PT (500.1.H)",IF(AND($K12=2,ISNUMBER($L12),COUNTIFS(nrES_PID,$D12,nrES_Code,$F12,nrES_Att,1)>0,SUMIFS(nrES_Raw,nrES_PID,$D12,nrES_Code,$F12,nrES_Att,1)>=$J12),"RETEST AFTER A PASSING FIRST ATTEMPT","OK"))))))))))
B13: =IF($C13="","",$D13&"-"&$F13&"-"&$K13) | D13: =IF($C13="","",IFERROR(INDEX(rngCadetPIDs,MATCH($C13,rngCadetNames,0)),"?")) | E13: =IF($D13="","",IFERROR(INDEX(nrCadetAgency,MATCH($D13,rngCadetPIDs,0)),"")) | G13: =IF($F13="","",IFERROR(INDEX(rngEPname,MATCH($F13,rngEPcode,0)),"?")) | H13: =IF($F13="","",IFERROR(INDEX(rngEPtype,MATCH($F13,rngEPcode,0)),"?")) | I13: =IF($F13="","",IFERROR(INDEX(rngEPseq,MATCH($F13,rngEPcode,0)),"")) | J13: =IF($F13="","",IFERROR(INDEX(rngEPpass,MATCH($F13,rngEPcode,0)),cfgPassingScore)) | M13: =IF($C13="","",IF($L13="","",IF(NOT(ISNUMBER($L13)),$L13,IF(N($K13)>2,"",IF($K13=1,IF(COUNTIFS(nrES_PID,$D13,nrES_Code,$F13,nrES_Att,2,nrES_Raw,">=0")>0,"",$L13),IF($L13>=$J13,MAX($J13,cfgRetakeRecordedCap),IF(COUNTIFS(nrES_PID,$D13,nrES_Code,$F13,nrES_Att,1)=0,$L13,SUMIFS(nrES_Raw,nrES_PID,$D13,nrES_Code,$F13,nrES_Att,1)))))))) | N13: =IF($C13="","",IF($L13="","",IF(NOT(ISNUMBER($L13)),"(not a score)",IF($L13>=$J13,"Yes","No")))) | O13: =IF($C13="","",IF($M13="","",IF(NOT(ISNUMBER($M13)),"(not a score)",IF($M13>=$J13,"Yes","No")))) | P13: =IF($C13="","",IF($K13="","",IF(N($K13)>2,"No",IF(COUNTIFS(nrES_PID,$D13,nrES_Code,$F13,nrES_Att,">"&$K13,nrES_Att,"<=2",nrES_Raw,">=0")=0,"Yes","No")))) | Q13: =IF($C13="","",IF($L13="","",IF(AND($K13=1,ISNUMBER($L13),$L13<$J13,COUNTIFS(nrES_PID,$D13,nrES_Code,$F13,nrES_Att,2,nrES_Raw,">=0")=0),"Yes","No"))) | R13: =IF($C13="","",IF($L13="","",IF(AND(N($K13)>=2,ISNUMBER($L13),$L13<$J13),"Yes","No"))) | T13: =IF(OR($C13="",$L13="",$K13<>1,NOT(ISNUMBER($L13)),$L13>=$J13),"",IF($S13="","(enter date)",_xlfn.LET(_xlpm.dn,_xlfn.XLOOKUP($S13,nrCDdate,nrCDnum,"",1),IF(_xlpm.dn="","(after last class day)",_xlfn.LET(_xlpm.dd,_xlfn.XLOOKUP(_xlpm.dn+cfgRetestClassDays,nrCDnum,nrCDdate,""),_xlpm.ok,_xlfn.XLOOKUP(_xlpm.dn+cfgRetestClassDays,nrCDnum,nrCDinsession,"No"),IF(OR(_xlpm.dd="",_xlpm.ok<>"Yes"),"(after last class day)",_xlpm.dd)))))) | U13: =IF($C13="","",IF(AND($Y13="Excused",$L13="",N($K13)<=1),"EXCUSED - 1st attempt pending",IF(OR($L13="",$K13<>1,NOT(ISNUMBER($L13)),$L13>=$J13),"",IF(COUNTIFS(nrES_PID,$D13,nrES_Code,$F13,nrES_Att,2,nrES_Raw,">=0")>0,IF(IFERROR(_xlfn.MINIFS(nrES_Date,nrES_PID,$D13,nrES_Code,$F13,nrES_Att,2,nrES_Raw,">=0",nrES_Date,">0"),0)=0,"RETEST UNDATED",IF(NOT(ISNUMBER($T13)),"RETEST DATE UNCHECKED",IF(_xlfn.MINIFS(nrES_Date,nrES_PID,$D13,nrES_Code,$F13,nrES_Att,2,nrES_Raw,">=0",nrES_Date,">0")>$T13,"LATE RETEST "&TEXT(_xlfn.MINIFS(nrES_Date,nrES_PID,$D13,nrES_Code,$F13,nrES_Att,2,nrES_Raw,">=0",nrES_Date,">0"),"mm/dd")&" (due "&TEXT($T13,"mm/dd")&")","Retested"))),IF(NOT(ISNUMBER($T13)),"CHECK DATE",IF(TODAY()>$T13,"OVERDUE","Due "&TEXT($T13,"mm/dd"))))))) | X13: =IF($C13="","",IF(AND($L13<>"",NOT(ISNUMBER($L13))),"RAW SCORE NOT A NUMBER",IF(AND(ISNUMBER($L13),OR($L13<0,$L13>100)),"RAW SCORE OUT OF RANGE",IF(AND($Y13="Unexcused",OR($L13="",NOT(ISNUMBER($L13)),$L13<>0)),"UNEXCUSED ABSENCE MUST RECORD 0",IF(COUNTIF(nrES_RecID,$B13)>1,"DUPLICATE RECORD",IF(N($K13)>2,"ATTEMPT 3+ NOT ALLOWED - policy 300.5 permits one retest per exam; this row records nothing",IF(AND($K13=2,COUNTIFS(nrES_PID,$D13,nrES_Code,$F13,nrES_Att,1)=0),"ATTEMPT 2 WITHOUT ATTEMPT 1",IF(AND($K13=2,$L13=""),"RETEST ROW HAS NO SCORE",IF(AND($H13="Final",$L13<>"",IFERROR(INDEX(nrCKfinalExamElig,MATCH($D13,rngCadetPIDs,0)),"")="No"),"FINAL EXAM AFTER FAILED FINAL PT (500.1.H)",IF(AND($K13=2,ISNUMBER($L13),COUNTIFS(nrES_PID,$D13,nrES_Code,$F13,nrES_Att,1)>0,SUMIFS(nrES_Raw,nrES_PID,$D13,nrES_Code,$F13,nrES_Att,1)>=$J13),"RETEST AFTER A PASSING FIRST ATTEMPT","OK"))))))))))
B14: =IF($C14="","",$D14&"-"&$F14&"-"&$K14) | D14: =IF($C14="","",IFERROR(INDEX(rngCadetPIDs,MATCH($C14,rngCadetNames,0)),"?")) | E14: =IF($D14="","",IFERROR(INDEX(nrCadetAgency,MATCH($D14,rngCadetPIDs,0)),"")) | G14: =IF($F14="","",IFERROR(INDEX(rngEPname,MATCH($F14,rngEPcode,0)),"?")) | H14: =IF($F14="","",IFERROR(INDEX(rngEPtype,MATCH($F14,rngEPcode,0)),"?")) | I14: =IF($F14="","",IFERROR(INDEX(rngEPseq,MATCH($F14,rngEPcode,0)),"")) | J14: =IF($F14="","",IFERROR(INDEX(rngEPpass,MATCH($F14,rngEPcode,0)),cfgPassingScore)) | M14: =IF($C14="","",IF($L14="","",IF(NOT(ISNUMBER($L14)),$L14,IF(N($K14)>2,"",IF($K14=1,IF(COUNTIFS(nrES_PID,$D14,nrES_Code,$F14,nrES_Att,2,nrES_Raw,">=0")>0,"",$L14),IF($L14>=$J14,MAX($J14,cfgRetakeRecordedCap),IF(COUNTIFS(nrES_PID,$D14,nrES_Code,$F14,nrES_Att,1)=0,$L14,SUMIFS(nrES_Raw,nrES_PID,$D14,nrES_Code,$F14,nrES_Att,1)))))))) | N14: =IF($C14="","",IF($L14="","",IF(NOT(ISNUMBER($L14)),"(not a score)",IF($L14>=$J14,"Yes","No")))) | O14: =IF($C14="","",IF($M14="","",IF(NOT(ISNUMBER($M14)),"(not a score)",IF($M14>=$J14,"Yes","No")))) | P14: =IF($C14="","",IF($K14="","",IF(N($K14)>2,"No",IF(COUNTIFS(nrES_PID,$D14,nrES_Code,$F14,nrES_Att,">"&$K14,nrES_Att,"<=2",nrES_Raw,">=0")=0,"Yes","No")))) | Q14: =IF($C14="","",IF($L14="","",IF(AND($K14=1,ISNUMBER($L14),$L14<$J14,COUNTIFS(nrES_PID,$D14,nrES_Code,$F14,nrES_Att,2,nrES_Raw,">=0")=0),"Yes","No"))) | R14: =IF($C14="","",IF($L14="","",IF(AND(N($K14)>=2,ISNUMBER($L14),$L14<$J14),"Yes","No"))) | T14: =IF(OR($C14="",$L14="",$K14<>1,NOT(ISNUMBER($L14)),$L14>=$J14),"",IF($S14="","(enter date)",_xlfn.LET(_xlpm.dn,_xlfn.XLOOKUP($S14,nrCDdate,nrCDnum,"",1),IF(_xlpm.dn="","(after last class day)",_xlfn.LET(_xlpm.dd,_xlfn.XLOOKUP(_xlpm.dn+cfgRetestClassDays,nrCDnum,nrCDdate,""),_xlpm.ok,_xlfn.XLOOKUP(_xlpm.dn+cfgRetestClassDays,nrCDnum,nrCDinsession,"No"),IF(OR(_xlpm.dd="",_xlpm.ok<>"Yes"),"(after last class day)",_xlpm.dd)))))) | U14: =IF($C14="","",IF(AND($Y14="Excused",$L14="",N($K14)<=1),"EXCUSED - 1st attempt pending",IF(OR($L14="",$K14<>1,NOT(ISNUMBER($L14)),$L14>=$J14),"",IF(COUNTIFS(nrES_PID,$D14,nrES_Code,$F14,nrES_Att,2,nrES_Raw,">=0")>0,IF(IFERROR(_xlfn.MINIFS(nrES_Date,nrES_PID,$D14,nrES_Code,$F14,nrES_Att,2,nrES_Raw,">=0",nrES_Date,">0"),0)=0,"RETEST UNDATED",IF(NOT(ISNUMBER($T14)),"RETEST DATE UNCHECKED",IF(_xlfn.MINIFS(nrES_Date,nrES_PID,$D14,nrES_Code,$F14,nrES_Att,2,nrES_Raw,">=0",nrES_Date,">0")>$T14,"LATE RETEST "&TEXT(_xlfn.MINIFS(nrES_Date,nrES_PID,$D14,nrES_Code,$F14,nrES_Att,2,nrES_Raw,">=0",nrES_Date,">0"),"mm/dd")&" (due "&TEXT($T14,"mm/dd")&")","Retested"))),IF(NOT(ISNUMBER($T14)),"CHECK DATE",IF(TODAY()>$T14,"OVERDUE","Due "&TEXT($T14,"mm/dd"))))))) | X14: =IF($C14="","",IF(AND($L14<>"",NOT(ISNUMBER($L14))),"RAW SCORE NOT A NUMBER",IF(AND(ISNUMBER($L14),OR($L14<0,$L14>100)),"RAW SCORE OUT OF RANGE",IF(AND($Y14="Unexcused",OR($L14="",NOT(ISNUMBER($L14)),$L14<>0)),"UNEXCUSED ABSENCE MUST RECORD 0",IF(COUNTIF(nrES_RecID,$B14)>1,"DUPLICATE RECORD",IF(N($K14)>2,"ATTEMPT 3+ NOT ALLOWED - policy 300.5 permits one retest per exam; this row records nothing",IF(AND($K14=2,COUNTIFS(nrES_PID,$D14,nrES_Code,$F14,nrES_Att,1)=0),"ATTEMPT 2 WITHOUT ATTEMPT 1",IF(AND($K14=2,$L14=""),"RETEST ROW HAS NO SCORE",IF(AND($H14="Final",$L14<>"",IFERROR(INDEX(nrCKfinalExamElig,MATCH($D14,rngCadetPIDs,0)),"")="No"),"FINAL EXAM AFTER FAILED FINAL PT (500.1.H)",IF(AND($K14=2,ISNUMBER($L14),COUNTIFS(nrES_PID,$D14,nrES_Code,$F14,nrES_Att,1)>0,SUMIFS(nrES_Raw,nrES_PID,$D14,nrES_Code,$F14,nrES_Att,1)>=$J14),"RETEST AFTER A PASSING FIRST ATTEMPT","OK"))))))))))
B15: =IF($C15="","",$D15&"-"&$F15&"-"&$K15) | D15: =IF($C15="","",IFERROR(INDEX(rngCadetPIDs,MATCH($C15,rngCadetNames,0)),"?")) | E15: =IF($D15="","",IFERROR(INDEX(nrCadetAgency,MATCH($D15,rngCadetPIDs,0)),"")) | G15: =IF($F15="","",IFERROR(INDEX(rngEPname,MATCH($F15,rngEPcode,0)),"?")) | H15: =IF($F15="","",IFERROR(INDEX(rngEPtype,MATCH($F15,rngEPcode,0)),"?")) | I15: =IF($F15="","",IFERROR(INDEX(rngEPseq,MATCH($F15,rngEPcode,0)),"")) | J15: =IF($F15="","",IFERROR(INDEX(rngEPpass,MATCH($F15,rngEPcode,0)),cfgPassingScore)) | M15: =IF($C15="","",IF($L15="","",IF(NOT(ISNUMBER($L15)),$L15,IF(N($K15)>2,"",IF($K15=1,IF(COUNTIFS(nrES_PID,$D15,nrES_Code,$F15,nrES_Att,2,nrES_Raw,">=0")>0,"",$L15),IF($L15>=$J15,MAX($J15,cfgRetakeRecordedCap),IF(COUNTIFS(nrES_PID,$D15,nrES_Code,$F15,nrES_Att,1)=0,$L15,SUMIFS(nrES_Raw,nrES_PID,$D15,nrES_Code,$F15,nrES_Att,1)))))))) | N15: =IF($C15="","",IF($L15="","",IF(NOT(ISNUMBER($L15)),"(not a score)",IF($L15>=$J15,"Yes","No")))) | O15: =IF($C15="","",IF($M15="","",IF(NOT(ISNUMBER($M15)),"(not a score)",IF($M15>=$J15,"Yes","No")))) | P15: =IF($C15="","",IF($K15="","",IF(N($K15)>2,"No",IF(COUNTIFS(nrES_PID,$D15,nrES_Code,$F15,nrES_Att,">"&$K15,nrES_Att,"<=2",nrES_Raw,">=0")=0,"Yes","No")))) | Q15: =IF($C15="","",IF($L15="","",IF(AND($K15=1,ISNUMBER($L15),$L15<$J15,COUNTIFS(nrES_PID,$D15,nrES_Code,$F15,nrES_Att,2,nrES_Raw,">=0")=0),"Yes","No"))) | R15: =IF($C15="","",IF($L15="","",IF(AND(N($K15)>=2,ISNUMBER($L15),$L15<$J15),"Yes","No"))) | T15: =IF(OR($C15="",$L15="",$K15<>1,NOT(ISNUMBER($L15)),$L15>=$J15),"",IF($S15="","(enter date)",_xlfn.LET(_xlpm.dn,_xlfn.XLOOKUP($S15,nrCDdate,nrCDnum,"",1),IF(_xlpm.dn="","(after last class day)",_xlfn.LET(_xlpm.dd,_xlfn.XLOOKUP(_xlpm.dn+cfgRetestClassDays,nrCDnum,nrCDdate,""),_xlpm.ok,_xlfn.XLOOKUP(_xlpm.dn+cfgRetestClassDays,nrCDnum,nrCDinsession,"No"),IF(OR(_xlpm.dd="",_xlpm.ok<>"Yes"),"(after last class day)",_xlpm.dd)))))) | U15: =IF($C15="","",IF(AND($Y15="Excused",$L15="",N($K15)<=1),"EXCUSED - 1st attempt pending",IF(OR($L15="",$K15<>1,NOT(ISNUMBER($L15)),$L15>=$J15),"",IF(COUNTIFS(nrES_PID,$D15,nrES_Code,$F15,nrES_Att,2,nrES_Raw,">=0")>0,IF(IFERROR(_xlfn.MINIFS(nrES_Date,nrES_PID,$D15,nrES_Code,$F15,nrES_Att,2,nrES_Raw,">=0",nrES_Date,">0"),0)=0,"RETEST UNDATED",IF(NOT(ISNUMBER($T15)),"RETEST DATE UNCHECKED",IF(_xlfn.MINIFS(nrES_Date,nrES_PID,$D15,nrES_Code,$F15,nrES_Att,2,nrES_Raw,">=0",nrES_Date,">0")>$T15,"LATE RETEST "&TEXT(_xlfn.MINIFS(nrES_Date,nrES_PID,$D15,nrES_Code,$F15,nrES_Att,2,nrES_Raw,">=0",nrES_Date,">0"),"mm/dd")&" (due "&TEXT($T15,"mm/dd")&")","Retested"))),IF(NOT(ISNUMBER($T15)),"CHECK DATE",IF(TODAY()>$T15,"OVERDUE","Due "&TEXT($T15,"mm/dd"))))))) | X15: =IF($C15="","",IF(AND($L15<>"",NOT(ISNUMBER($L15))),"RAW SCORE NOT A NUMBER",IF(AND(ISNUMBER($L15),OR($L15<0,$L15>100)),"RAW SCORE OUT OF RANGE",IF(AND($Y15="Unexcused",OR($L15="",NOT(ISNUMBER($L15)),$L15<>0)),"UNEXCUSED ABSENCE MUST RECORD 0",IF(COUNTIF(nrES_RecID,$B15)>1,"DUPLICATE RECORD",IF(N($K15)>2,"ATTEMPT 3+ NOT ALLOWED - policy 300.5 permits one retest per exam; this row records nothing",IF(AND($K15=2,COUNTIFS(nrES_PID,$D15,nrES_Code,$F15,nrES_Att,1)=0),"ATTEMPT 2 WITHOUT ATTEMPT 1",IF(AND($K15=2,$L15=""),"RETEST ROW HAS NO SCORE",IF(AND($H15="Final",$L15<>"",IFERROR(INDEX(nrCKfinalExamElig,MATCH($D15,rngCadetPIDs,0)),"")="No"),"FINAL EXAM AFTER FAILED FINAL PT (500.1.H)",IF(AND($K15=2,ISNUMBER($L15),COUNTIFS(nrES_PID,$D15,nrES_Code,$F15,nrES_Att,1)>0,SUMIFS(nrES_Raw,nrES_PID,$D15,nrES_Code,$F15,nrES_Att,1)>=$J15),"RETEST AFTER A PASSING FIRST ATTEMPT","OK"))))))))))
B16: =IF($C16="","",$D16&"-"&$F16&"-"&$K16) | D16: =IF($C16="","",IFERROR(INDEX(rngCadetPIDs,MATCH($C16,rngCadetNames,0)),"?")) | E16: =IF($D16="","",IFERROR(INDEX(nrCadetAgency,MATCH($D16,rngCadetPIDs,0)),"")) | G16: =IF($F16="","",IFERROR(INDEX(rngEPname,MATCH($F16,rngEPcode,0)),"?")) | H16: =IF($F16="","",IFERROR(INDEX(rngEPtype,MATCH($F16,rngEPcode,0)),"?")) | I16: =IF($F16="","",IFERROR(INDEX(rngEPseq,MATCH($F16,rngEPcode,0)),"")) | J16: =IF($F16="","",IFERROR(INDEX(rngEPpass,MATCH($F16,rngEPcode,0)),cfgPassingScore)) | M16: =IF($C16="","",IF($L16="","",IF(NOT(ISNUMBER($L16)),$L16,IF(N($K16)>2,"",IF($K16=1,IF(COUNTIFS(nrES_PID,$D16,nrES_Code,$F16,nrES_Att,2,nrES_Raw,">=0")>0,"",$L16),IF($L16>=$J16,MAX($J16,cfgRetakeRecordedCap),IF(COUNTIFS(nrES_PID,$D16,nrES_Code,$F16,nrES_Att,1)=0,$L16,SUMIFS(nrES_Raw,nrES_PID,$D16,nrES_Code,$F16,nrES_Att,1)))))))) | N16: =IF($C16="","",IF($L16="","",IF(NOT(ISNUMBER($L16)),"(not a score)",IF($L16>=$J16,"Yes","No")))) | O16: =IF($C16="","",IF($M16="","",IF(NOT(ISNUMBER($M16)),"(not a score)",IF($M16>=$J16,"Yes","No")))) | P16: =IF($C16="","",IF($K16="","",IF(N($K16)>2,"No",IF(COUNTIFS(nrES_PID,$D16,nrES_Code,$F16,nrES_Att,">"&$K16,nrES_Att,"<=2",nrES_Raw,">=0")=0,"Yes","No")))) | Q16: =IF($C16="","",IF($L16="","",IF(AND($K16=1,ISNUMBER($L16),$L16<$J16,COUNTIFS(nrES_PID,$D16,nrES_Code,$F16,nrES_Att,2,nrES_Raw,">=0")=0),"Yes","No"))) | R16: =IF($C16="","",IF($L16="","",IF(AND(N($K16)>=2,ISNUMBER($L16),$L16<$J16),"Yes","No"))) | T16: =IF(OR($C16="",$L16="",$K16<>1,NOT(ISNUMBER($L16)),$L16>=$J16),"",IF($S16="","(enter date)",_xlfn.LET(_xlpm.dn,_xlfn.XLOOKUP($S16,nrCDdate,nrCDnum,"",1),IF(_xlpm.dn="","(after last class day)",_xlfn.LET(_xlpm.dd,_xlfn.XLOOKUP(_xlpm.dn+cfgRetestClassDays,nrCDnum,nrCDdate,""),_xlpm.ok,_xlfn.XLOOKUP(_xlpm.dn+cfgRetestClassDays,nrCDnum,nrCDinsession,"No"),IF(OR(_xlpm.dd="",_xlpm.ok<>"Yes"),"(after last class day)",_xlpm.dd)))))) | U16: =IF($C16="","",IF(AND($Y16="Excused",$L16="",N($K16)<=1),"EXCUSED - 1st attempt pending",IF(OR($L16="",$K16<>1,NOT(ISNUMBER($L16)),$L16>=$J16),"",IF(COUNTIFS(nrES_PID,$D16,nrES_Code,$F16,nrES_Att,2,nrES_Raw,">=0")>0,IF(IFERROR(_xlfn.MINIFS(nrES_Date,nrES_PID,$D16,nrES_Code,$F16,nrES_Att,2,nrES_Raw,">=0",nrES_Date,">0"),0)=0,"RETEST UNDATED",IF(NOT(ISNUMBER($T16)),"RETEST DATE UNCHECKED",IF(_xlfn.MINIFS(nrES_Date,nrES_PID,$D16,nrES_Code,$F16,nrES_Att,2,nrES_Raw,">=0",nrES_Date,">0")>$T16,"LATE RETEST "&TEXT(_xlfn.MINIFS(nrES_Date,nrES_PID,$D16,nrES_Code,$F16,nrES_Att,2,nrES_Raw,">=0",nrES_Date,">0"),"mm/dd")&" (due "&TEXT($T16,"mm/dd")&")","Retested"))),IF(NOT(ISNUMBER($T16)),"CHECK DATE",IF(TODAY()>$T16,"OVERDUE","Due "&TEXT($T16,"mm/dd"))))))) | X16: =IF($C16="","",IF(AND($L16<>"",NOT(ISNUMBER($L16))),"RAW SCORE NOT A NUMBER",IF(AND(ISNUMBER($L16),OR($L16<0,$L16>100)),"RAW SCORE OUT OF RANGE",IF(AND($Y16="Unexcused",OR($L16="",NOT(ISNUMBER($L16)),$L16<>0)),"UNEXCUSED ABSENCE MUST RECORD 0",IF(COUNTIF(nrES_RecID,$B16)>1,"DUPLICATE RECORD",IF(N($K16)>2,"ATTEMPT 3+ NOT ALLOWED - policy 300.5 permits one retest per exam; this row records nothing",IF(AND($K16=2,COUNTIFS(nrES_PID,$D16,nrES_Code,$F16,nrES_Att,1)=0),"ATTEMPT 2 WITHOUT ATTEMPT 1",IF(AND($K16=2,$L16=""),"RETEST ROW HAS NO SCORE",IF(AND($H16="Final",$L16<>"",IFERROR(INDEX(nrCKfinalExamElig,MATCH($D16,rngCadetPIDs,0)),"")="No"),"FINAL EXAM AFTER FAILED FINAL PT (500.1.H)",IF(AND($K16=2,ISNUMBER($L16),COUNTIFS(nrES_PID,$D16,nrES_Code,$F16,nrES_Att,1)>0,SUMIFS(nrES_Raw,nrES_PID,$D16,nrES_Code,$F16,nrES_Att,1)>=$J16),"RETEST AFTER A PASSING FIRST ATTEMPT","OK"))))))))))
