Workbook

Sheet Dashboard
A1: TPD TRAINING UNIT — COMMAND DASHBOARD
A2: What needs doing today. Lists refresh themselves; buttons drive the paperwork for the record picked in ACTIVE RECORD.
B4: ACTIVE ▶ | C4: T26-003 | D4: =IF(ActiveRow=0,"← pick a tracking # — all forms & emails use it",INDEX(Requests!$C$2:$C$251,ActiveRow)&" • "&INDEX(Requests!$K$2:$K$251,ActiveRow)) -> SAMPLE — A. Chen • Advanced Crash Reconstruction | N4: Today: | O4: =TODAY() -> 46243 | R4: =IFERROR(MATCH(ActiveTrk,Requests!$A$2:$A$251,0),0) -> 3
B6: BUDGET (FY) | D6: SPENT | G6: ENCUMBERED (open est.) | I6: REMAINING | L6: REQUESTS (FY) | N6: DEPARTING ≤ 30 DAYS
B7: =Budget_Total -> 75000 | D7: =SUM(Requests!$AY$2:$AY$251) -> 889.07 | G7: =SUM(Requests!$AZ$2:$AZ$251) -> 2601 | I7: =Budget_Total-SUM(Requests!$AY$2:$AY$251)-SUM(Requests!$AZ$2:$AZ$251) -> 71509.93 | L7: =SUMPRODUCT((Requests!$A$2:$A$251<>"")*1) -> 4 | N7: =SUMPRODUCT((Requests!$P$2:$P$251>=TODAY())*(Requests!$P$2:$P$251<=TODAY()+30)*(Requests!$A$2:$A$251<>"")*(Requests!$B$2:$B$251<>"Denied")*(Requests!$B$2:$B$251<>"Cancelled")) -> 1
B10: ="1 — AWAITING APPROVAL ("&COUNTIF(Requests!$BA$2:$BA$251,">0")&")" -> 1 — AWAITING APPROVAL (1) | G10: ="2 — NEEDS REGISTRATION ("&COUNTIF(Requests!$BB$2:$BB$251,">0")&")" -> 2 — NEEDS REGISTRATION (1) | L10: ="3 — NEEDS HOTEL ("&COUNTIF(Requests!$BC$2:$BC$251,">0")&")" -> 3 — NEEDS HOTEL (1)
B11: Trk | C11: Officer | D11: Course | E11: Submitted | G11: Trk | H11: Officer | I11: Course | J11: Departs | L11: Trk | M11: Officer | N11: Course | O11: Departs
B12: =IF($S12="","",INDEX(Requests!$A$2:$A$251,$S12)) -> T26-004 | C12: =IF($S12="","",INDEX(Requests!$C$2:$C$251,$S12)) -> SAMPLE — T. Okafor | D12: =IF($S12="","",INDEX(Requests!$K$2:$K$251,$S12)) -> Crisis Intervention Training | E12: =IF($S12="","",INDEX(Requests!$AN$2:$AN$251,$S12)) -> 46240 | G12: =IF($T12="","",INDEX(Requests!$A$2:$A$251,$T12)) -> T26-003 | H12: =IF($T12="","",INDEX(Requests!$C$2:$C$251,$T12)) -> SAMPLE — A. Chen | I12: =IF($T12="","",INDEX(Requests!$K$2:$K$251,$T12)) -> Advanced Crash Reconstruction | J12: =IF($T12="","",INDEX(Requests!$P$2:$P$251,$T12)) -> 46257 | L12: =IF($U12="","",INDEX(Requests!$A$2:$A$251,$U12)) -> T26-003 | M12: =IF($U12="","",INDEX(Requests!$C$2:$C$251,$U12)) -> SAMPLE — A. Chen | N12: =IF($U12="","",INDEX(Requests!$K$2:$K$251,$U12)) -> Advanced Crash Reconstruction | O12: =IF($U12="","",INDEX(Requests!$P$2:$P$251,$U12)) -> 46257 | S12: =IFERROR(MATCH(1,Requests!$BA$2:$BA$251,0),"") -> 4 | T12: =IFERROR(MATCH(1,Requests!$BB$2:$BB$251,0),"") -> 3 | U12: =IFERROR(MATCH(1,Requests!$BC$2:$BC$251,0),"") -> 3
B13: =IF($S13="","",INDEX(Requests!$A$2:$A$251,$S13)) | C13: =IF($S13="","",INDEX(Requests!$C$2:$C$251,$S13)) | D13: =IF($S13="","",INDEX(Requests!$K$2:$K$251,$S13)) | E13: =IF($S13="","",INDEX(Requests!$AN$2:$AN$251,$S13)) | G13: =IF($T13="","",INDEX(Requests!$A$2:$A$251,$T13)) | H13: =IF($T13="","",INDEX(Requests!$C$2:$C$251,$T13)) | I13: =IF($T13="","",INDEX(Requests!$K$2:$K$251,$T13)) | J13: =IF($T13="","",INDEX(Requests!$P$2:$P$251,$T13)) | L13: =IF($U13="","",INDEX(Requests!$A$2:$A$251,$U13)) | M13: =IF($U13="","",INDEX(Requests!$C$2:$C$251,$U13)) | N13: =IF($U13="","",INDEX(Requests!$K$2:$K$251,$U13)) | O13: =IF($U13="","",INDEX(Requests!$P$2:$P$251,$U13)) | S13: =IFERROR(MATCH(2,Requests!$BA$2:$BA$251,0),"") | T13: =IFERROR(MATCH(2,Requests!$BB$2:$BB$251,0),"") | U13: =IFERROR(MATCH(2,Requests!$BC$2:$BC$251,0),"")
B14: =IF($S14="","",INDEX(Requests!$A$2:$A$251,$S14)) | C14: =IF($S14="","",INDEX(Requests!$C$2:$C$251,$S14)) | D14: =IF($S14="","",INDEX(Requests!$K$2:$K$251,$S14)) | E14: =IF($S14="","",INDEX(Requests!$AN$2:$AN$251,$S14)) | G14: =IF($T14="","",INDEX(Requests!$A$2:$A$251,$T14)) | H14: =IF($T14="","",INDEX(Requests!$C$2:$C$251,$T14)) | I14: =IF($T14="","",INDEX(Requests!$K$2:$K$251,$T14)) | J14: =IF($T14="","",INDEX(Requests!$P$2:$P$251,$T14)) | L14: =IF($U14="","",INDEX(Requests!$A$2:$A$251,$U14)) | M14: =IF($U14="","",INDEX(Requests!$C$2:$C$251,$U14)) | N14: =IF($U14="","",INDEX(Requests!$K$2:$K$251,$U14)) | O14: =IF($U14="","",INDEX(Requests!$P$2:$P$251,$U14)) | S14: =IFERROR(MATCH(3,Requests!$BA$2:$BA$251,0),"") | T14: =IFERROR(MATCH(3,Requests!$BB$2:$BB$251,0),"") | U14: =IFERROR(MATCH(3,Requests!$BC$2:$BC$251,0),"")
B15: =IF($S15="","",INDEX(Requests!$A$2:$A$251,$S15)) | C15: =IF($S15="","",INDEX(Requests!$C$2:$C$251,$S15)) | D15: =IF($S15="","",INDEX(Requests!$K$2:$K$251,$S15)) | E15: =IF($S15="","",INDEX(Requests!$AN$2:$AN$251,$S15)) | G15: =IF($T15="","",INDEX(Requests!$A$2:$A$251,$T15)) | H15: =IF($T15="","",INDEX(Requests!$C$2:$C$251,$T15)) | I15: =IF($T15="","",INDEX(Requests!$K$2:$K$251,$T15)) | J15: =IF($T15="","",INDEX(Requests!$P$2:$P$251,$T15)) | L15: =IF($U15="","",INDEX(Requests!$A$2:$A$251,$U15)) | M15: =IF($U15="","",INDEX(Requests!$C$2:$C$251,$U15)) | N15: =IF($U15="","",INDEX(Requests!$K$2:$K$251,$U15)) | O15: =IF($U15="","",INDEX(Requests!$P$2:$P$251,$U15)) | S15: =IFERROR(MATCH(4,Requests!$BA$2:$BA$251,0),"") | T15: =IFERROR(MATCH(4,Requests!$BB$2:$BB$251,0),"") | U15: =IFERROR(MATCH(4,Requests!$BC$2:$BC$251,0),"")
B16: =IF($S16="","",INDEX(Requests!$A$2:$A$251,$S16)) | C16: =IF($S16="","",INDEX(Requests!$C$2:$C$251,$S16)) | D16: =IF($S16="","",INDEX(Requests!$K$2:$K$251,$S16)) | E16: =IF($S16="","",INDEX(Requests!$AN$2:$AN$251,$S16)) | G16: =IF($T16="","",INDEX(Requests!$A$2:$A$251,$T16)) | H16: =IF($T16="","",INDEX(Requests!$C$2:$C$251,$T16)) | I16: =IF($T16="","",INDEX(Requests!$K$2:$K$251,$T16)) | J16: =IF($T16="","",INDEX(Requests!$P$2:$P$251,$T16)) | L16: =IF($U16="","",INDEX(Requests!$A$2:$A$251,$U16)) | M16: =IF($U16="","",INDEX(Requests!$C$2:$C$251,$U16)) | N16: =IF($U16="","",INDEX(Requests!$K$2:$K$251,$U16)) | O16: =IF($U16="","",INDEX(Requests!$P$2:$P$251,$U16)) | S16: =IFERROR(MATCH(5,Requests!$BA$2:$BA$251,0),"") | T16: =IFERROR(MATCH(5,Requests!$BB$2:$BB$251,0),"") | U16: =IFERROR(MATCH(5,Requests!$BC$2:$BC$251,0),"")
B17: =IF($S17="","",INDEX(Requests!$A$2:$A$251,$S17)) | C17: =IF($S17="","",INDEX(Requests!$C$2:$C$251,$S17)) | D17: =IF($S17="","",INDEX(Requests!$K$2:$K$251,$S17)) | E17: =IF($S17="","",INDEX(Requests!$AN$2:$AN$251,$S17)) | G17: =IF($T17="","",INDEX(Requests!$A$2:$A$251,$T17)) | H17: =IF($T17="","",INDEX(Requests!$C$2:$C$251,$T17)) | I17: =IF($T17="","",INDEX(Requests!$K$2:$K$251,$T17)) | J17: =IF($T17="","",INDEX(Requests!$P$2:$P$251,$T17)) | L17: =IF($U17="","",INDEX(Requests!$A$2:$A$251,$U17)) | M17: =IF($U17="","",INDEX(Requests!$C$2:$C$251,$U17)) | N17: =IF($U17="","",INDEX(Requests!$K$2:$K$251,$U17)) | O17: =IF($U17="","",INDEX(Requests!$P$2:$P$251,$U17)) | S17: =IFERROR(MATCH(6,Requests!$BA$2:$BA$251,0),"") | T17: =IFERROR(MATCH(6,Requests!$BB$2:$BB$251,0),"") | U17: =IFERROR(MATCH(6,Requests!$BC$2:$BC$251,0),"")
B18: =IF($S18="","",INDEX(Requests!$A$2:$A$251,$S18)) | C18: =IF($S18="","",INDEX(Requests!$C$2:$C$251,$S18)) | D18: =IF($S18="","",INDEX(Requests!$K$2:$K$251,$S18)) | E18: =IF($S18="","",INDEX(Requests!$AN$2:$AN$251,$S18)) | G18: =IF($T18="","",INDEX(Requests!$A$2:$A$251,$T18)) | H18: =IF($T18="","",INDEX(Requests!$C$2:$C$251,$T18)) | I18: =IF($T18="","",INDEX(Requests!$K$2:$K$251,$T18)) | J18: =IF($T18="","",INDEX(Requests!$P$2:$P$251,$T18)) | L18: =IF($U18="","",INDEX(Requests!$A$2:$A$251,$U18)) | M18: =IF($U18="","",INDEX(Requests!$C$2:$C$251,$U18)) | N18: =IF($U18="","",INDEX(Requests!$K$2:$K$251,$U18)) | O18: =IF($U18="","",INDEX(Requests!$P$2:$P$251,$U18)) | S18: =IFERROR(MATCH(7,Requests!$BA$2:$BA$251,0),"") | T18: =IFERROR(MATCH(7,Requests!$BB$2:$BB$251,0),"") | U18: =IFERROR(MATCH(7,Requests!$BC$2:$BC$251,0),"")
B19: =IF($S19="","",INDEX(Requests!$A$2:$A$251,$S19)) | C19: =IF($S19="","",INDEX(Requests!$C$2:$C$251,$S19)) | D19: =IF($S19="","",INDEX(Requests!$K$2:$K$251,$S19)) | E19: =IF($S19="","",INDEX(Requests!$AN$2:$AN$251,$S19)) | G19: =IF($T19="","",INDEX(Requests!$A$2:$A$251,$T19)) | H19: =IF($T19="","",INDEX(Requests!$C$2:$C$251,$T19)) | I19: =IF($T19="","",INDEX(Requests!$K$2:$K$251,$T19)) | J19: =IF($T19="","",INDEX(Requests!$P$2:$P$251,$T19)) | L19: =IF($U19="","",INDEX(Requests!$A$2:$A$251,$U19)) | M19: =IF($U19="","",INDEX(Requests!$C$2:$C$251,$U19)) | N19: =IF($U19="","",INDEX(Requests!$K$2:$K$251,$U19)) | O19: =IF($U19="","",INDEX(Requests!$P$2:$P$251,$U19)) | S19: =IFERROR(MATCH(8,Requests!$BA$2:$BA$251,0),"") | T19: =IFERROR(MATCH(8,Requests!$BB$2:$BB$251,0),"") | U19: =IFERROR(MATCH(8,Requests!$BC$2:$BC$251,0),"")
B22: ="4 — RECEIPTS OVERDUE ("&COUNTIF(Requests!$BD$2:$BD$251,">0")&")" -> 4 — RECEIPTS OVERDUE (1) | G22: ="5 — FINANCE PACKET DUE ≤ 7 DAYS (Tuesday NOON) ("&COUNTIF(Requests!$BE$2:$BE$251,">0")&")" -> 5 — FINANCE PACKET DUE ≤ 7 DAYS (Tuesday NOON) (2)
B23: Trk | C23: Officer | D23: Course | E23: Was Due | G23: Trk | H23: Officer | I23: Course | J23: Due (Tue)
B24: =IF($V24="","",INDEX(Requests!$A$2:$A$251,$V24)) -> T26-002 | C24: =IF($V24="","",INDEX(Requests!$C$2:$C$251,$V24)) -> SAMPLE — M. Rivera | D24: =IF($V24="","",INDEX(Requests!$K$2:$K$251,$V24)) -> Homicide Investigation | E24: =IF($V24="","",INDEX(Requests!$AR$2:$AR$251,$V24)) -> 46238 | G24: =IF($R24="","",INDEX(Requests!$A$2:$A$251,$R24)) -> T26-002 | H24: =IF($R24="","",INDEX(Requests!$C$2:$C$251,$R24)) -> SAMPLE — M. Rivera | I24: =IF($R24="","",INDEX(Requests!$K$2:$K$251,$R24)) -> Homicide Investigation | J24: =IF($R24="","",INDEX(Requests!$AT$2:$AT$251,$R24)) -> 46217 | R24: =IFERROR(MATCH(1,Requests!$BE$2:$BE$251,0),"") -> 2 | V24: =IFERROR(MATCH(1,Requests!$BD$2:$BD$251,0),"") -> 2
B25: =IF($V25="","",INDEX(Requests!$A$2:$A$251,$V25)) | C25: =IF($V25="","",INDEX(Requests!$C$2:$C$251,$V25)) | D25: =IF($V25="","",INDEX(Requests!$K$2:$K$251,$V25)) | E25: =IF($V25="","",INDEX(Requests!$AR$2:$AR$251,$V25)) | G25: =IF($R25="","",INDEX(Requests!$A$2:$A$251,$R25)) -> T26-003 | H25: =IF($R25="","",INDEX(Requests!$C$2:$C$251,$R25)) -> SAMPLE — A. Chen | I25: =IF($R25="","",INDEX(Requests!$K$2:$K$251,$R25)) -> Advanced Crash Reconstruction | J25: =IF($R25="","",INDEX(Requests!$AT$2:$AT$251,$R25)) -> 46245 | R25: =IFERROR(MATCH(2,Requests!$BE$2:$BE$251,0),"") -> 3 | V25: =IFERROR(MATCH(2,Requests!$BD$2:$BD$251,0),"")
B26: =IF($V26="","",INDEX(Requests!$A$2:$A$251,$V26)) | C26: =IF($V26="","",INDEX(Requests!$C$2:$C$251,$V26)) | D26: =IF($V26="","",INDEX(Requests!$K$2:$K$251,$V26)) | E26: =IF($V26="","",INDEX(Requests!$AR$2:$AR$251,$V26)) | G26: =IF($R26="","",INDEX(Requests!$A$2:$A$251,$R26)) | H26: =IF($R26="","",INDEX(Requests!$C$2:$C$251,$R26)) | I26: =IF($R26="","",INDEX(Requests!$K$2:$K$251,$R26)) | J26: =IF($R26="","",INDEX(Requests!$AT$2:$AT$251,$R26)) | R26: =IFERROR(MATCH(3,Requests!$BE$2:$BE$251,0),"") | V26: =IFERROR(MATCH(3,Requests!$BD$2:$BD$251,0),"")
B27: =IF($V27="","",INDEX(Requests!$A$2:$A$251,$V27)) | C27: =IF($V27="","",INDEX(Requests!$C$2:$C$251,$V27)) | D27: =IF($V27="","",INDEX(Requests!$K$2:$K$251,$V27)) | E27: =IF($V27="","",INDEX(Requests!$AR$2:$AR$251,$V27)) | G27: =IF($R27="","",INDEX(Requests!$A$2:$A$251,$R27)) | H27: =IF($R27="","",INDEX(Requests!$C$2:$C$251,$R27)) | I27: =IF($R27="","",INDEX(Requests!$K$2:$K$251,$R27)) | J27: =IF($R27="","",INDEX(Requests!$AT$2:$AT$251,$R27)) | R27: =IFERROR(MATCH(4,Requests!$BE$2:$BE$251,0),"") | V27: =IFERROR(MATCH(4,Requests!$BD$2:$BD$251,0),"")
B28: =IF($V28="","",INDEX(Requests!$A$2:$A$251,$V28)) | C28: =IF($V28="","",INDEX(Requests!$C$2:$C$251,$V28)) | D28: =IF($V28="","",INDEX(Requests!$K$2:$K$251,$V28)) | E28: =IF($V28="","",INDEX(Requests!$AR$2:$AR$251,$V28)) | G28: =IF($R28="","",INDEX(Requests!$A$2:$A$251,$R28)) | H28: =IF($R28="","",INDEX(Requests!$C$2:$C$251,$R28)) | I28: =IF($R28="","",INDEX(Requests!$K$2:$K$251,$R28)) | J28: =IF($R28="","",INDEX(Requests!$AT$2:$AT$251,$R28)) | R28: =IFERROR(MATCH(5,Requests!$BE$2:$BE$251,0),"") | V28: =IFERROR(MATCH(5,Requests!$BD$2:$BD$251,0),"")
B29: =IF($V29="","",INDEX(Requests!$A$2:$A$251,$V29)) | C29: =IF($V29="","",INDEX(Requests!$C$2:$C$251,$V29)) | D29: =IF($V29="","",INDEX(Requests!$K$2:$K$251,$V29)) | E29: =IF($V29="","",INDEX(Requests!$AR$2:$AR$251,$V29)) | G29: =IF($R29="","",INDEX(Requests!$A$2:$A$251,$R29)) | H29: =IF($R29="","",INDEX(Requests!$C$2:$C$251,$R29)) | I29: =IF($R29="","",INDEX(Requests!$K$2:$K$251,$R29)) | J29: =IF($R29="","",INDEX(Requests!$AT$2:$AT$251,$R29)) | R29: =IFERROR(MATCH(6,Requests!$BE$2:$BE$251,0),"") | V29: =IFERROR(MATCH(6,Requests!$BD$2:$BD$251,0),"")
B30: =IF($V30="","",INDEX(Requests!$A$2:$A$251,$V30)) | C30: =IF($V30="","",INDEX(Requests!$C$2:$C$251,$V30)) | D30: =IF($V30="","",INDEX(Requests!$K$2:$K$251,$V30)) | E30: =IF($V30="","",INDEX(Requests!$AR$2:$AR$251,$V30)) | G30: =IF($R30="","",INDEX(Requests!$A$2:$A$251,$R30)) | H30: =IF($R30="","",INDEX(Requests!$C$2:$C$251,$R30)) | I30: =IF($R30="","",INDEX(Requests!$K$2:$K$251,$R30)) | J30: =IF($R30="","",INDEX(Requests!$AT$2:$AT$251,$R30)) | R30: =IFERROR(MATCH(7,Requests!$BE$2:$BE$251,0),"") | V30: =IFERROR(MATCH(7,Requests!$BD$2:$BD$251,0),"")
B31: =IF($V31="","",INDEX(Requests!$A$2:$A$251,$V31)) | C31: =IF($V31="","",INDEX(Requests!$C$2:$C$251,$V31)) | D31: =IF($V31="","",INDEX(Requests!$K$2:$K$251,$V31)) | E31: =IF($V31="","",INDEX(Requests!$AR$2:$AR$251,$V31)) | G31: =IF($R31="","",INDEX(Requests!$A$2:$A$251,$R31)) | H31: =IF($R31="","",INDEX(Requests!$C$2:$C$251,$R31)) | I31: =IF($R31="","",INDEX(Requests!$K$2:$K$251,$R31)) | J31: =IF($R31="","",INDEX(Requests!$AT$2:$AT$251,$R31)) | R31: =IFERROR(MATCH(8,Requests!$BE$2:$BE$251,0),"") | V31: =IFERROR(MATCH(8,Requests!$BD$2:$BD$251,0),"")
B33: BUTTONS (added by the one-time installer): Import Requests • Draft Approval Email • Draft Officer Notification • Draft Settlement Email • Print Packet (PDF) • Push Deadlines to Outlook • Archive Year
B35: No buttons? Press Alt+F8 and run the same macros by name. Emails always OPEN FOR REVIEW — nothing sends itself. Calendar push only adds items not already pushed (Cal Pushed? column).

Sheet Requests
A1: Tracking # | B1: Status | C1: Officer | D1: Rank | E1: Emp ID | F1: Division | G1: Officer Email | H1: Phone | I1: Supervisor | J1: Supervisor Email | K1: Course / Event | L1: Provider | M1: Location | N1: Class Start | O1: Class End | P1: Depart Date | Q1: Depart Time | R1: Return Date | S1: Return Time | T1: Registration Est | U1: Nights | V1: Lodging Rate | W1: Lodging Est | X1: Travel Mode | Y1: Miles (RT) | Z1: Airfare/Other Trv | AA1: Travel Est | AB1: Per Diem Est | AC1: Other Est | AD1: TOTAL EST | AE1: Registration Act | AF1: Lodging Act | AG1: Travel Act | AH1: Per Diem Act | AI1: Other Act | AJ1: TOTAL ACT | AK1: Paid Direct by City | AL1: Advance to Traveler | AM1: Balance Due Traveler | AN1: Submitted | AO1: Approved | AP1: Registered? | AQ1: Hotel Booked? | AR1: Receipts Due | AS1: Receipts Rec'd | AT1: Finance Packet Due (Tue noon) | AU1: Sent to Finance | AV1: Cal Pushed? | AW1: Coordinator Notes | AX1: hEst | AY1: hSpent | AZ1: hOpen | BA1: qApproval | BB1: qRegister | BC1: qHotel | BD1: qReceipts | BE1: qFinance | BF1: TCOLE # | BG1: Website | BH1: Other Desc | BI1: Justification
A2: T26-001 | B2: Closed | C2: SAMPLE — J. Doe | D2: Officer | E2: 4101 | F2: Patrol | G2: jdoe@example.com | H2: 903-555-0101 | I2: Sgt. R. Lee | J2: rlee@example.com | K2: Interview & Interrogation | L2: TMPA | M2: Plano, TX | N2: 46090 | O2: 46092 | P2: 46089 | Q2: 0.625 | R2: 46092 | S2: 0.77083333 | T2: 350 | U2: 3 | V2: 119 | W2: =IF($A2="","",N($U2)*N($V2)) -> 357 | X2: City Vehicle | Y2: 0 | Z2: 0 | AA2: =IF($A2="","",IF($X2="POV",N($Y2)*MileageRate,0)+N($Z2)) -> 0 | AB2: =IF(OR($A2="",$P2="",$R2="",$Q2="",$S2=""),"",IF($R2=$P2,($Q2<=T_DepBfast)*($S2>=T_RetBfast)*PD_Bfast+($Q2<=T_DepLunch)*($S2>=T_RetLunch)*PD_Lunch+($Q2<=T_DepDinner)*($S2>=T_RetDinner)*PD_Dinner+PD_Incid,($Q2<=T_DepBfast)*PD_Bfast+($Q2<=T_DepLunch)*PD_Lunch+($Q2<=T_DepDinner)*PD_Dinner+($S2>=T_RetBfast)*PD_Bfast+($S2>=T_RetLunch)*PD_Lunch+($S2>=T_RetDinner)*PD_Dinner+MAX($R2-$P2-1,0)*(PD_Bfast+PD_Lunch+PD_Dinner)+($R2-$P2+1)*PD_Incid)) -> 182 | AC2: 0 | AD2: =IF($A2="","",N($T2)+N($W2)+N($AA2)+N($AB2)+N($AC2)) -> 889 | AE2: 350 | AF2: 371.07 | AG2: 0 | AH2: 168 | AI2: 0 | AJ2: =IF($A2="","",IF(COUNT($AE2:$AI2)=0,"",SUM($AE2:$AI2))) -> 889.07 | AK2: 721.07 | AL2: 168 | AM2: =IF(OR($A2="",$AJ2=""),"",$AJ2-N($AK2)-N($AL2)) -> 0 | AN2: 46034 | AO2: 46037 | AP2: Y | AQ2: Y | AR2: =IF(OR($A2="",$R2=""),"",$R2+ReceiptDays) -> 46099 | AS2: 46097 | AT2: =IF(OR($A2="",$P2=""),"",($P2-FinanceLeadDays)-MOD(($P2-FinanceLeadDays)-DATE(2024,1,2),7)) -> 46077 | AU2: 46098 | AV2: Y | AX2: =IF(OR($A2="",$B2="Denied",$B2="Cancelled"),0,N($AD2)) -> 889 | AY2: =IF($A2="",0,N($AJ2)) -> 889.07 | AZ2: =IF(OR($A2="",$B2="Denied",$B2="Cancelled",$B2="Closed"),0,IF(N($AJ2)>0,0,N($AD2))) -> 0 | BA2: =IF($A2="",0,IF($B2="Awaiting Approval",COUNTIF(BA$1:BA1,">0")+1,0)) -> 0 | BB2: =IF($A2="",0,IF(AND($B2="Approved",$AP2<>"Y"),COUNTIF(BB$1:BB1,">0")+1,0)) -> 0 | BC2: =IF($A2="",0,IF(AND($B2="Approved",N($U2)>0,$AQ2<>"Y"),COUNTIF(BC$1:BC1,">0")+1,0)) -> 0 | BD2: =IF($A2="",0,IF(AND($AR2<>"",N($AR2)<TODAY(),$AS2="",$B2<>"Closed",$B2<>"Cancelled",$B2<>"Denied"),COUNTIF(BD$1:BD1,">0")+1,0)) -> 0 | BE2: =IF($A2="",0,IF(AND($AT2<>"",N($AT2)<=TODAY()+7,$AU2="",$B2<>"Denied",$B2<>"Cancelled",$B2<>"Closed"),COUNTIF(BE$1:BE1,">0")+1,0)) -> 0 | BI2: TCOLE intermediate certificate requirement.
A3: T26-002 | B3: Travel Complete | C3: SAMPLE — M. Rivera | D3: Detective | E3: 3877 | F3: CID | G3: mrivera@example.com | H3: 903-555-0102 | I3: Lt. K. Ford | J3: kford@example.com | K3: Homicide Investigation | L3: ILEETA | M3: Dallas, TX | N3: 46230 | O3: 46231 | P3: 46230 | Q3: 0.27083333 | R3: 46231 | S3: 0.79166667 | T3: 425 | U3: 1 | V3: 139 | W3: =IF($A3="","",N($U3)*N($V3)) -> 139 | X3: POV | Y3: 190 | Z3: 0 | AA3: =IF($A3="","",IF($X3="POV",N($Y3)*MileageRate,0)+N($Z3)) -> 133 | AB3: =IF(OR($A3="",$P3="",$R3="",$Q3="",$S3=""),"",IF($R3=$P3,($Q3<=T_DepBfast)*($S3>=T_RetBfast)*PD_Bfast+($Q3<=T_DepLunch)*($S3>=T_RetLunch)*PD_Lunch+($Q3<=T_DepDinner)*($S3>=T_RetDinner)*PD_Dinner+PD_Incid,($Q3<=T_DepBfast)*PD_Bfast+($Q3<=T_DepLunch)*PD_Lunch+($Q3<=T_DepDinner)*PD_Dinner+($S3>=T_RetBfast)*PD_Bfast+($S3>=T_RetLunch)*PD_Lunch+($S3>=T_RetDinner)*PD_Dinner+MAX($R3-$P3-1,0)*(PD_Bfast+PD_Lunch+PD_Dinner)+($R3-$P3+1)*PD_Incid)) -> 105 | AC3: 0 | AD3: =IF($A3="","",N($T3)+N($W3)+N($AA3)+N($AB3)+N($AC3)) -> 802 | AJ3: =IF($A3="","",IF(COUNT($AE3:$AI3)=0,"",SUM($AE3:$AI3))) | AM3: =IF(OR($A3="",$AJ3=""),"",$AJ3-N($AK3)-N($AL3)) | AN3: 46174 | AO3: 46176 | AP3: Y | AQ3: Y | AR3: =IF(OR($A3="",$R3=""),"",$R3+ReceiptDays) -> 46238 | AT3: =IF(OR($A3="",$P3=""),"",($P3-FinanceLeadDays)-MOD(($P3-FinanceLeadDays)-DATE(2024,1,2),7)) -> 46217 | AV3: Y | AX3: =IF(OR($A3="",$B3="Denied",$B3="Cancelled"),0,N($AD3)) -> 802 | AY3: =IF($A3="",0,N($AJ3)) -> 0 | AZ3: =IF(OR($A3="",$B3="Denied",$B3="Cancelled",$B3="Closed"),0,IF(N($AJ3)>0,0,N($AD3))) -> 802 | BA3: =IF($A3="",0,IF($B3="Awaiting Approval",COUNTIF(BA$1:BA2,">0")+1,0)) -> 0 | BB3: =IF($A3="",0,IF(AND($B3="Approved",$AP3<>"Y"),COUNTIF(BB$1:BB2,">0")+1,0)) -> 0 | BC3: =IF($A3="",0,IF(AND($B3="Approved",N($U3)>0,$AQ3<>"Y"),COUNTIF(BC$1:BC2,">0")+1,0)) -> 0 | BD3: =IF($A3="",0,IF(AND($AR3<>"",N($AR3)<TODAY(),$AS3="",$B3<>"Closed",$B3<>"Cancelled",$B3<>"Denied"),COUNTIF(BD$1:BD2,">0")+1,0)) -> 1 | BE3: =IF($A3="",0,IF(AND($AT3<>"",N($AT3)<=TODAY()+7,$AU3="",$B3<>"Denied",$B3<>"Cancelled",$B3<>"Closed"),COUNTIF(BE$1:BE2,">0")+1,0)) -> 1 | BI3: Case-load requires homicide certification.
A4: T26-003 | B4: Approved | C4: SAMPLE — A. Chen | D4: Corporal | E4: 4215 | F4: Traffic | G4: achen@example.com | H4: 903-555-0103 | I4: Sgt. R. Lee | J4: rlee@example.com | K4: Advanced Crash Reconstruction | L4: TEEX | M4: College Station, TX | N4: 46258 | O4: 46262 | P4: 46257 | Q4: 0.54166667 | R4: 46262 | S4: 0.77083333 | T4: 450 | U4: 5 | V4: 129 | W4: =IF($A4="","",N($U4)*N($V4)) -> 645 | X4: City Vehicle | Y4: 0 | Z4: 0 | AA4: =IF($A4="","",IF($X4="POV",N($Y4)*MileageRate,0)+N($Z4)) -> 0 | AB4: =IF(OR($A4="",$P4="",$R4="",$Q4="",$S4=""),"",IF($R4=$P4,($Q4<=T_DepBfast)*($S4>=T_RetBfast)*PD_Bfast+($Q4<=T_DepLunch)*($S4>=T_RetLunch)*PD_Lunch+($Q4<=T_DepDinner)*($S4>=T_RetDinner)*PD_Dinner+PD_Incid,($Q4<=T_DepBfast)*PD_Bfast+($Q4<=T_DepLunch)*PD_Lunch+($Q4<=T_DepDinner)*PD_Dinner+($S4>=T_RetBfast)*PD_Bfast+($S4>=T_RetLunch)*PD_Lunch+($S4>=T_RetDinner)*PD_Dinner+MAX($R4-$P4-1,0)*(PD_Bfast+PD_Lunch+PD_Dinner)+($R4-$P4+1)*PD_Incid)) -> 300 | AC4: 35 | AD4: =IF($A4="","",N($T4)+N($W4)+N($AA4)+N($AB4)+N($AC4)) -> 1430 | AJ4: =IF($A4="","",IF(COUNT($AE4:$AI4)=0,"",SUM($AE4:$AI4))) | AM4: =IF(OR($A4="",$AJ4=""),"",$AJ4-N($AK4)-N($AL4)) | AN4: 46223 | AO4: 46227 | AR4: =IF(OR($A4="",$R4=""),"",$R4+ReceiptDays) -> 46269 | AT4: =IF(OR($A4="",$P4=""),"",($P4-FinanceLeadDays)-MOD(($P4-FinanceLeadDays)-DATE(2024,1,2),7)) -> 46245 | AX4: =IF(OR($A4="",$B4="Denied",$B4="Cancelled"),0,N($AD4)) -> 1430 | AY4: =IF($A4="",0,N($AJ4)) -> 0 | AZ4: =IF(OR($A4="",$B4="Denied",$B4="Cancelled",$B4="Closed"),0,IF(N($AJ4)>0,0,N($AD4))) -> 1430 | BA4: =IF($A4="",0,IF($B4="Awaiting Approval",COUNTIF(BA$1:BA3,">0")+1,0)) -> 0 | BB4: =IF($A4="",0,IF(AND($B4="Approved",$AP4<>"Y"),COUNTIF(BB$1:BB3,">0")+1,0)) -> 1 | BC4: =IF($A4="",0,IF(AND($B4="Approved",N($U4)>0,$AQ4<>"Y"),COUNTIF(BC$1:BC3,">0")+1,0)) -> 1 | BD4: =IF($A4="",0,IF(AND($AR4<>"",N($AR4)<TODAY(),$AS4="",$B4<>"Closed",$B4<>"Cancelled",$B4<>"Denied"),COUNTIF(BD$1:BD3,">0")+1,0)) -> 0 | BE4: =IF($A4="",0,IF(AND($AT4<>"",N($AT4)<=TODAY()+7,$AU4="",$B4<>"Denied",$B4<>"Cancelled",$B4<>"Closed"),COUNTIF(BE$1:BE3,">0")+1,0)) -> 2 | BI4: Required for accident-investigator certification.
A5: T26-004 | B5: Awaiting Approval | C5: SAMPLE — T. Okafor | D5: Officer | E5: 4302 | F5: Patrol | G5: tokafor@example.com | H5: 903-555-0104 | I5: Sgt. B. Hall | J5: bhall@example.com | K5: Crisis Intervention Training | L5: TCOLE Reg. Academy | M5: Longview, TX | N5: 46280 | O5: 46282 | P5: 46280 | Q5: 0.25 | R5: 46282 | S5: 0.72916667 | T5: 0 | U5: 2 | V5: 109 | W5: =IF($A5="","",N($U5)*N($V5)) -> 218 | X5: City Vehicle | Y5: 0 | Z5: 0 | AA5: =IF($A5="","",IF($X5="POV",N($Y5)*MileageRate,0)+N($Z5)) -> 0 | AB5: =IF(OR($A5="",$P5="",$R5="",$Q5="",$S5=""),"",IF($R5=$P5,($Q5<=T_DepBfast)*($S5>=T_RetBfast)*PD_Bfast+($Q5<=T_DepLunch)*($S5>=T_RetLunch)*PD_Lunch+($Q5<=T_DepDinner)*($S5>=T_RetDinner)*PD_Dinner+PD_Incid,($Q5<=T_DepBfast)*PD_Bfast+($Q5<=T_DepLunch)*PD_Lunch+($Q5<=T_DepDinner)*PD_Dinner+($S5>=T_RetBfast)*PD_Bfast+($S5>=T_RetLunch)*PD_Lunch+($S5>=T_RetDinner)*PD_Dinner+MAX($R5-$P5-1,0)*(PD_Bfast+PD_Lunch+PD_Dinner)+($R5-$P5+1)*PD_Incid)) -> 151 | AC5: 0 | AD5: =IF($A5="","",N($T5)+N($W5)+N($AA5)+N($AB5)+N($AC5)) -> 369 | AJ5: =IF($A5="","",IF(COUNT($AE5:$AI5)=0,"",SUM($AE5:$AI5))) | AM5: =IF(OR($A5="",$AJ5=""),"",$AJ5-N($AK5)-N($AL5)) | AN5: 46240 | AR5: =IF(OR($A5="",$R5=""),"",$R5+ReceiptDays) -> 46289 | AT5: =IF(OR($A5="",$P5=""),"",($P5-FinanceLeadDays)-MOD(($P5-FinanceLeadDays)-DATE(2024,1,2),7)) -> 46273 | AX5: =IF(OR($A5="",$B5="Denied",$B5="Cancelled"),0,N($AD5)) -> 369 | AY5: =IF($A5="",0,N($AJ5)) -> 0 | AZ5: =IF(OR($A5="",$B5="Denied",$B5="Cancelled",$B5="Closed"),0,IF(N($AJ5)>0,0,N($AD5))) -> 369 | BA5: =IF($A5="",0,IF($B5="Awaiting Approval",COUNTIF(BA$1:BA4,">0")+1,0)) -> 1 | BB5: =IF($A5="",0,IF(AND($B5="Approved",$AP5<>"Y"),COUNTIF(BB$1:BB4,">0")+1,0)) -> 0 | BC5: =IF($A5="",0,IF(AND($B5="Approved",N($U5)>0,$AQ5<>"Y"),COUNTIF(BC$1:BC4,">0")+1,0)) -> 0 | BD5: =IF($A5="",0,IF(AND($AR5<>"",N($AR5)<TODAY(),$AS5="",$B5<>"Closed",$B5<>"Cancelled",$B5<>"Denied"),COUNTIF(BD$1:BD4,">0")+1,0)) -> 0 | BE5: =IF($A5="",0,IF(AND($AT5<>"",N($AT5)<=TODAY()+7,$AU5="",$B5<>"Denied",$B5<>"Cancelled",$B5<>"Closed"),COUNTIF(BE$1:BE4,">0")+1,0)) -> 0 | BI5: 40-hr CIT — department mental-health response initiative.
W6: =IF($A6="","",N($U6)*N($V6)) | AA6: =IF($A6="","",IF($X6="POV",N($Y6)*MileageRate,0)+N($Z6)) | AB6: =IF(OR($A6="",$P6="",$R6="",$Q6="",$S6=""),"",IF($R6=$P6,($Q6<=T_DepBfast)*($S6>=T_RetBfast)*PD_Bfast+($Q6<=T_DepLunch)*($S6>=T_RetLunch)*PD_Lunch+($Q6<=T_DepDinner)*($S6>=T_RetDinner)*PD_Dinner+PD_Incid,($Q6<=T_DepBfast)*PD_Bfast+($Q6<=T_DepLunch)*PD_Lunch+($Q6<=T_DepDinner)*PD_Dinner+($S6>=T_RetBfast)*PD_Bfast+($S6>=T_RetLunch)*PD_Lunch+($S6>=T_RetDinner)*PD_Dinner+MAX($R6-$P6-1,0)*(PD_Bfast+PD_Lunch+PD_Dinner)+($R6-$P6+1)*PD_Incid)) | AD6: =IF($A6="","",N($T6)+N($W6)+N($AA6)+N($AB6)+N($AC6)) | AJ6: =IF($A6="","",IF(COUNT($AE6:$AI6)=0,"",SUM($AE6:$AI6))) | AM6: =IF(OR($A6="",$AJ6=""),"",$AJ6-N($AK6)-N($AL6)) | AR6: =IF(OR($A6="",$R6=""),"",$R6+ReceiptDays) | AT6: =IF(OR($A6="",$P6=""),"",($P6-FinanceLeadDays)-MOD(($P6-FinanceLeadDays)-DATE(2024,1,2),7)) | AX6: =IF(OR($A6="",$B6="Denied",$B6="Cancelled"),0,N($AD6)) -> 0 | AY6: =IF($A6="",0,N($AJ6)) -> 0 | AZ6: =IF(OR($A6="",$B6="Denied",$B6="Cancelled",$B6="Closed"),0,IF(N($AJ6)>0,0,N($AD6))) -> 0 | BA6: =IF($A6="",0,IF($B6="Awaiting Approval",COUNTIF(BA$1:BA5,">0")+1,0)) -> 0 | BB6: =IF($A6="",0,IF(AND($B6="Approved",$AP6<>"Y"),COUNTIF(BB$1:BB5,">0")+1,0)) -> 0 | BC6: =IF($A6="",0,IF(AND($B6="Approved",N($U6)>0,$AQ6<>"Y"),COUNTIF(BC$1:BC5,">0")+1,0)) -> 0 | BD6: =IF($A6="",0,IF(AND($AR6<>"",N($AR6)<TODAY(),$AS6="",$B6<>"Closed",$B6<>"Cancelled",$B6<>"Denied"),COUNTIF(BD$1:BD5,">0")+1,0)) -> 0 | BE6: =IF($A6="",0,IF(AND($AT6<>"",N($AT6)<=TODAY()+7,$AU6="",$B6<>"Denied",$B6<>"Cancelled",$B6<>"Closed"),COUNTIF(BE$1:BE5,">0")+1,0)) -> 0
W7: =IF($A7="","",N($U7)*N($V7)) | AA7: =IF($A7="","",IF($X7="POV",N($Y7)*MileageRate,0)+N($Z7)) | AB7: =IF(OR($A7="",$P7="",$R7="",$Q7="",$S7=""),"",IF($R7=$P7,($Q7<=T_DepBfast)*($S7>=T_RetBfast)*PD_Bfast+($Q7<=T_DepLunch)*($S7>=T_RetLunch)*PD_Lunch+($Q7<=T_DepDinner)*($S7>=T_RetDinner)*PD_Dinner+PD_Incid,($Q7<=T_DepBfast)*PD_Bfast+($Q7<=T_DepLunch)*PD_Lunch+($Q7<=T_DepDinner)*PD_Dinner+($S7>=T_RetBfast)*PD_Bfast+($S7>=T_RetLunch)*PD_Lunch+($S7>=T_RetDinner)*PD_Dinner+MAX($R7-$P7-1,0)*(PD_Bfast+PD_Lunch+PD_Dinner)+($R7-$P7+1)*PD_Incid)) | AD7: =IF($A7="","",N($T7)+N($W7)+N($AA7)+N($AB7)+N($AC7)) | AJ7: =IF($A7="","",IF(COUNT($AE7:$AI7)=0,"",SUM($AE7:$AI7))) | AM7: =IF(OR($A7="",$AJ7=""),"",$AJ7-N($AK7)-N($AL7)) | AR7: =IF(OR($A7="",$R7=""),"",$R7+ReceiptDays) | AT7: =IF(OR($A7="",$P7=""),"",($P7-FinanceLeadDays)-MOD(($P7-FinanceLeadDays)-DATE(2024,1,2),7)) | AX7: =IF(OR($A7="",$B7="Denied",$B7="Cancelled"),0,N($AD7)) -> 0 | AY7: =IF($A7="",0,N($AJ7)) -> 0 | AZ7: =IF(OR($A7="",$B7="Denied",$B7="Cancelled",$B7="Closed"),0,IF(N($AJ7)>0,0,N($AD7))) -> 0 | BA7: =IF($A7="",0,IF($B7="Awaiting Approval",COUNTIF(BA$1:BA6,">0")+1,0)) -> 0 | BB7: =IF($A7="",0,IF(AND($B7="Approved",$AP7<>"Y"),COUNTIF(BB$1:BB6,">0")+1,0)) -> 0 | BC7: =IF($A7="",0,IF(AND($B7="Approved",N($U7)>0,$AQ7<>"Y"),COUNTIF(BC$1:BC6,">0")+1,0)) -> 0 | BD7: =IF($A7="",0,IF(AND($AR7<>"",N($AR7)<TODAY(),$AS7="",$B7<>"Closed",$B7<>"Cancelled",$B7<>"Denied"),COUNTIF(BD$1:BD6,">0")+1,0)) -> 0 | BE7: =IF($A7="",0,IF(AND($AT7<>"",N($AT7)<=TODAY()+7,$AU7="",$B7<>"Denied",$B7<>"Cancelled",$B7<>"Closed"),COUNTIF(BE$1:BE6,">0")+1,0)) -> 0
W8: =IF($A8="","",N($U8)*N($V8)) | AA8: =IF($A8="","",IF($X8="POV",N($Y8)*MileageRate,0)+N($Z8)) | AB8: =IF(OR($A8="",$P8="",$R8="",$Q8="",$S8=""),"",IF($R8=$P8,($Q8<=T_DepBfast)*($S8>=T_RetBfast)*PD_Bfast+($Q8<=T_DepLunch)*($S8>=T_RetLunch)*PD_Lunch+($Q8<=T_DepDinner)*($S8>=T_RetDinner)*PD_Dinner+PD_Incid,($Q8<=T_DepBfast)*PD_Bfast+($Q8<=T_DepLunch)*PD_Lunch+($Q8<=T_DepDinner)*PD_Dinner+($S8>=T_RetBfast)*PD_Bfast+($S8>=T_RetLunch)*PD_Lunch+($S8>=T_RetDinner)*PD_Dinner+MAX($R8-$P8-1,0)*(PD_Bfast+PD_Lunch+PD_Dinner)+($R8-$P8+1)*PD_Incid)) | AD8: =IF($A8="","",N($T8)+N($W8)+N($AA8)+N($AB8)+N($AC8)) | AJ8: =IF($A8="","",IF(COUNT($AE8:$AI8)=0,"",SUM($AE8:$AI8))) | AM8: =IF(OR($A8="",$AJ8=""),"",$AJ8-N($AK8)-N($AL8)) | AR8: =IF(OR($A8="",$R8=""),"",$R8+ReceiptDays) | AT8: =IF(OR($A8="",$P8=""),"",($P8-FinanceLeadDays)-MOD(($P8-FinanceLeadDays)-DATE(2024,1,2),7)) | AX8: =IF(OR($A8="",$B8="Denied",$B8="Cancelled"),0,N($AD8)) -> 0 | AY8: =IF($A8="",0,N($AJ8)) -> 0 | AZ8: =IF(OR($A8="",$B8="Denied",$B8="Cancelled",$B8="Closed"),0,IF(N($AJ8)>0,0,N($AD8))) -> 0 | BA8: =IF($A8="",0,IF($B8="Awaiting Approval",COUNTIF(BA$1:BA7,">0")+1,0)) -> 0 | BB8: =IF($A8="",0,IF(AND($B8="Approved",$AP8<>"Y"),COUNTIF(BB$1:BB7,">0")+1,0)) -> 0 | BC8: =IF($A8="",0,IF(AND($B8="Approved",N($U8)>0,$AQ8<>"Y"),COUNTIF(BC$1:BC7,">0")+1,0)) -> 0 | BD8: =IF($A8="",0,IF(AND($AR8<>"",N($AR8)<TODAY(),$AS8="",$B8<>"Closed",$B8<>"Cancelled",$B8<>"Denied"),COUNTIF(BD$1:BD7,">0")+1,0)) -> 0 | BE8: =IF($A8="",0,IF(AND($AT8<>"",N($AT8)<=TODAY()+7,$AU8="",$B8<>"Denied",$B8<>"Cancelled",$B8<>"Closed"),COUNTIF(BE$1:BE7,">0")+1,0)) -> 0
W9: =IF($A9="","",N($U9)*N($V9)) | AA9: =IF($A9="","",IF($X9="POV",N($Y9)*MileageRate,0)+N($Z9)) | AB9: =IF(OR($A9="",$P9="",$R9="",$Q9="",$S9=""),"",IF($R9=$P9,($Q9<=T_DepBfast)*($S9>=T_RetBfast)*PD_Bfast+($Q9<=T_DepLunch)*($S9>=T_RetLunch)*PD_Lunch+($Q9<=T_DepDinner)*($S9>=T_RetDinner)*PD_Dinner+PD_Incid,($Q9<=T_DepBfast)*PD_Bfast+($Q9<=T_DepLunch)*PD_Lunch+($Q9<=T_DepDinner)*PD_Dinner+($S9>=T_RetBfast)*PD_Bfast+($S9>=T_RetLunch)*PD_Lunch+($S9>=T_RetDinner)*PD_Dinner+MAX($R9-$P9-1,0)*(PD_Bfast+PD_Lunch+PD_Dinner)+($R9-$P9+1)*PD_Incid)) | AD9: =IF($A9="","",N($T9)+N($W9)+N($AA9)+N($AB9)+N($AC9)) | AJ9: =IF($A9="","",IF(COUNT($AE9:$AI9)=0,"",SUM($AE9:$AI9))) | AM9: =IF(OR($A9="",$AJ9=""),"",$AJ9-N($AK9)-N($AL9)) | AR9: =IF(OR($A9="",$R9=""),"",$R9+ReceiptDays) | AT9: =IF(OR($A9="",$P9=""),"",($P9-FinanceLeadDays)-MOD(($P9-FinanceLeadDays)-DATE(2024,1,2),7)) | AX9: =IF(OR($A9="",$B9="Denied",$B9="Cancelled"),0,N($AD9)) -> 0 | AY9: =IF($A9="",0,N($AJ9)) -> 0 | AZ9: =IF(OR($A9="",$B9="Denied",$B9="Cancelled",$B9="Closed"),0,IF(N($AJ9)>0,0,N($AD9))) -> 0 | BA9: =IF($A9="",0,IF($B9="Awaiting Approval",COUNTIF(BA$1:BA8,">0")+1,0)) -> 0 | BB9: =IF($A9="",0,IF(AND($B9="Approved",$AP9<>"Y"),COUNTIF(BB$1:BB8,">0")+1,0)) -> 0 | BC9: =IF($A9="",0,IF(AND($B9="Approved",N($U9)>0,$AQ9<>"Y"),COUNTIF(BC$1:BC8,">0")+1,0)) -> 0 | BD9: =IF($A9="",0,IF(AND($AR9<>"",N($AR9)<TODAY(),$AS9="",$B9<>"Closed",$B9<>"Cancelled",$B9<>"Denied"),COUNTIF(BD$1:BD8,">0")+1,0)) -> 0 | BE9: =IF($A9="",0,IF(AND($AT9<>"",N($AT9)<=TODAY()+7,$AU9="",$B9<>"Denied",$B9<>"Cancelled",$B9<>"Closed"),COUNTIF(BE$1:BE8,">0")+1,0)) -> 0
W10: =IF($A10="","",N($U10)*N($V10)) | AA10: =IF($A10="","",IF($X10="POV",N($Y10)*MileageRate,0)+N($Z10)) | AB10: =IF(OR($A10="",$P10="",$R10="",$Q10="",$S10=""),"",IF($R10=$P10,($Q10<=T_DepBfast)*($S10>=T_RetBfast)*PD_Bfast+($Q10<=T_DepLunch)*($S10>=T_RetLunch)*PD_Lunch+($Q10<=T_DepDinner)*($S10>=T_RetDinner)*PD_Dinner+PD_Incid,($Q10<=T_DepBfast)*PD_Bfast+($Q10<=T_DepLunch)*PD_Lunch+($Q10<=T_DepDinner)*PD_Dinner+($S10>=T_RetBfast)*PD_Bfast+($S10>=T_RetLunch)*PD_Lunch+($S10>=T_RetDinner)*PD_Dinner+MAX($R10-$P10-1,0)*(PD_Bfast+PD_Lunch+PD_Dinner)+($R10-$P10+1)*PD_Incid)) | AD10: =IF($A10="","",N($T10)+N($W10)+N($AA10)+N($AB10)+N($AC10)) | AJ10: =IF($A10="","",IF(COUNT($AE10:$AI10)=0,"",SUM($AE10:$AI10))) | AM10: =IF(OR($A10="",$AJ10=""),"",$AJ10-N($AK10)-N($AL10)) | AR10: =IF(OR($A10="",$R10=""),"",$R10+ReceiptDays) | AT10: =IF(OR($A10="",$P10=""),"",($P10-FinanceLeadDays)-MOD(($P10-FinanceLeadDays)-DATE(2024,1,2),7)) | AX10: =IF(OR($A10="",$B10="Denied",$B10="Cancelled"),0,N($AD10)) -> 0 | AY10: =IF($A10="",0,N($AJ10)) -> 0 | AZ10: =IF(OR($A10="",$B10="Denied",$B10="Cancelled",$B10="Closed"),0,IF(N($AJ10)>0,0,N($AD10))) -> 0 | BA10: =IF($A10="",0,IF($B10="Awaiting Approval",COUNTIF(BA$1:BA9,">0")+1,0)) -> 0 | BB10: =IF($A10="",0,IF(AND($B10="Approved",$AP10<>"Y"),COUNTIF(BB$1:BB9,">0")+1,0)) -> 0 | BC10: =IF($A10="",0,IF(AND($B10="Approved",N($U10)>0,$AQ10<>"Y"),COUNTIF(BC$1:BC9,">0")+1,0)) -> 0 | BD10: =IF($A10="",0,IF(AND($AR10<>"",N($AR10)<TODAY(),$AS10="",$B10<>"Closed",$B10<>"Cancelled",$B10<>"Denied"),COUNTIF(BD$1:BD9,">0")+1,0)) -> 0 | BE10: =IF($A10="",0,IF(AND($AT10<>"",N($AT10)<=TODAY()+7,$AU10="",$B10<>"Denied",$B10<>"Cancelled",$B10<>"Closed"),COUNTIF(BE$1:BE9,">0")+1,0)) -> 0
W11: =IF($A11="","",N($U11)*N($V11)) | AA11: =IF($A11="","",IF($X11="POV",N($Y11)*MileageRate,0)+N($Z11)) | AB11: =IF(OR($A11="",$P11="",$R11="",$Q11="",$S11=""),"",IF($R11=$P11,($Q11<=T_DepBfast)*($S11>=T_RetBfast)*PD_Bfast+($Q11<=T_DepLunch)*($S11>=T_RetLunch)*PD_Lunch+($Q11<=T_DepDinner)*($S11>=T_RetDinner)*PD_Dinner+PD_Incid,($Q11<=T_DepBfast)*PD_Bfast+($Q11<=T_DepLunch)*PD_Lunch+($Q11<=T_DepDinner)*PD_Dinner+($S11>=T_RetBfast)*PD_Bfast+($S11>=T_RetLunch)*PD_Lunch+($S11>=T_RetDinner)*PD_Dinner+MAX($R11-$P11-1,0)*(PD_Bfast+PD_Lunch+PD_Dinner)+($R11-$P11+1)*PD_Incid)) | AD11: =IF($A11="","",N($T11)+N($W11)+N($AA11)+N($AB11)+N($AC11)) | AJ11: =IF($A11="","",IF(COUNT($AE11:$AI11)=0,"",SUM($AE11:$AI11))) | AM11: =IF(OR($A11="",$AJ11=""),"",$AJ11-N($AK11)-N($AL11)) | AR11: =IF(OR($A11="",$R11=""),"",$R11+ReceiptDays) | AT11: =IF(OR($A11="",$P11=""),"",($P11-FinanceLeadDays)-MOD(($P11-FinanceLeadDays)-DATE(2024,1,2),7)) | AX11: =IF(OR($A11="",$B11="Denied",$B11="Cancelled"),0,N($AD11)) -> 0 | AY11: =IF($A11="",0,N($AJ11)) -> 0 | AZ11: =IF(OR($A11="",$B11="Denied",$B11="Cancelled",$B11="Closed"),0,IF(N($AJ11)>0,0,N($AD11))) -> 0 | BA11: =IF($A11="",0,IF($B11="Awaiting Approval",COUNTIF(BA$1:BA10,">0")+1,0)) -> 0 | BB11: =IF($A11="",0,IF(AND($B11="Approved",$AP11<>"Y"),COUNTIF(BB$1:BB10,">0")+1,0)) -> 0 | BC11: =IF($A11="",0,IF(AND($B11="Approved",N($U11)>0,$AQ11<>"Y"),COUNTIF(BC$1:BC10,">0")+1,0)) -> 0 | BD11: =IF($A11="",0,IF(AND($AR11<>"",N($AR11)<TODAY(),$AS11="",$B11<>"Closed",$B11<>"Cancelled",$B11<>"Denied"),COUNTIF(BD$1:BD10,">0")+1,0)) -> 0 | BE11: =IF($A11="",0,IF(AND($AT11<>"",N($AT11)<=TODAY()+7,$AU11="",$B11<>"Denied",$B11<>"Cancelled",$B11<>"Closed"),COUNTIF(BE$1:BE10,">0")+1,0)) -> 0
W12: =IF($A12="","",N($U12)*N($V12)) | AA12: =IF($A12="","",IF($X12="POV",N($Y12)*MileageRate,0)+N($Z12)) | AB12: =IF(OR($A12="",$P12="",$R12="",$Q12="",$S12=""),"",IF($R12=$P12,($Q12<=T_DepBfast)*($S12>=T_RetBfast)*PD_Bfast+($Q12<=T_DepLunch)*($S12>=T_RetLunch)*PD_Lunch+($Q12<=T_DepDinner)*($S12>=T_RetDinner)*PD_Dinner+PD_Incid,($Q12<=T_DepBfast)*PD_Bfast+($Q12<=T_DepLunch)*PD_Lunch+($Q12<=T_DepDinner)*PD_Dinner+($S12>=T_RetBfast)*PD_Bfast+($S12>=T_RetLunch)*PD_Lunch+($S12>=T_RetDinner)*PD_Dinner+MAX($R12-$P12-1,0)*(PD_Bfast+PD_Lunch+PD_Dinner)+($R12-$P12+1)*PD_Incid)) | AD12: =IF($A12="","",N($T12)+N($W12)+N($AA12)+N($AB12)+N($AC12)) | AJ12: =IF($A12="","",IF(COUNT($AE12:$AI12)=0,"",SUM($AE12:$AI12))) | AM12: =IF(OR($A12="",$AJ12=""),"",$AJ12-N($AK12)-N($AL12)) | AR12: =IF(OR($A12="",$R12=""),"",$R12+ReceiptDays) | AT12: =IF(OR($A12="",$P12=""),"",($P12-FinanceLeadDays)-MOD(($P12-FinanceLeadDays)-DATE(2024,1,2),7)) | AX12: =IF(OR($A12="",$B12="Denied",$B12="Cancelled"),0,N($AD12)) -> 0 | AY12: =IF($A12="",0,N($AJ12)) -> 0 | AZ12: =IF(OR($A12="",$B12="Denied",$B12="Cancelled",$B12="Closed"),0,IF(N($AJ12)>0,0,N($AD12))) -> 0 | BA12: =IF($A12="",0,IF($B12="Awaiting Approval",COUNTIF(BA$1:BA11,">0")+1,0)) -> 0 | BB12: =IF($A12="",0,IF(AND($B12="Approved",$AP12<>"Y"),COUNTIF(BB$1:BB11,">0")+1,0)) -> 0 | BC12: =IF($A12="",0,IF(AND($B12="Approved",N($U12)>0,$AQ12<>"Y"),COUNTIF(BC$1:BC11,">0")+1,0)) -> 0 | BD12: =IF($A12="",0,IF(AND($AR12<>"",N($AR12)<TODAY(),$AS12="",$B12<>"Closed",$B12<>"Cancelled",$B12<>"Denied"),COUNTIF(BD$1:BD11,">0")+1,0)) -> 0 | BE12: =IF($A12="",0,IF(AND($AT12<>"",N($AT12)<=TODAY()+7,$AU12="",$B12<>"Denied",$B12<>"Cancelled",$B12<>"Closed"),COUNTIF(BE$1:BE11,">0")+1,0)) -> 0
W13: =IF($A13="","",N($U13)*N($V13)) | AA13: =IF($A13="","",IF($X13="POV",N($Y13)*MileageRate,0)+N($Z13)) | AB13: =IF(OR($A13="",$P13="",$R13="",$Q13="",$S13=""),"",IF($R13=$P13,($Q13<=T_DepBfast)*($S13>=T_RetBfast)*PD_Bfast+($Q13<=T_DepLunch)*($S13>=T_RetLunch)*PD_Lunch+($Q13<=T_DepDinner)*($S13>=T_RetDinner)*PD_Dinner+PD_Incid,($Q13<=T_DepBfast)*PD_Bfast+($Q13<=T_DepLunch)*PD_Lunch+($Q13<=T_DepDinner)*PD_Dinner+($S13>=T_RetBfast)*PD_Bfast+($S13>=T_RetLunch)*PD_Lunch+($S13>=T_RetDinner)*PD_Dinner+MAX($R13-$P13-1,0)*(PD_Bfast+PD_Lunch+PD_Dinner)+($R13-$P13+1)*PD_Incid)) | AD13: =IF($A13="","",N($T13)+N($W13)+N($AA13)+N($AB13)+N($AC13)) | AJ13: =IF($A13="","",IF(COUNT($AE13:$AI13)=0,"",SUM($AE13:$AI13))) | AM13: =IF(OR($A13="",$AJ13=""),"",$AJ13-N($AK13)-N($AL13)) | AR13: =IF(OR($A13="",$R13=""),"",$R13+ReceiptDays) | AT13: =IF(OR($A13="",$P13=""),"",($P13-FinanceLeadDays)-MOD(($P13-FinanceLeadDays)-DATE(2024,1,2),7)) | AX13: =IF(OR($A13="",$B13="Denied",$B13="Cancelled"),0,N($AD13)) -> 0 | AY13: =IF($A13="",0,N($AJ13)) -> 0 | AZ13: =IF(OR($A13="",$B13="Denied",$B13="Cancelled",$B13="Closed"),0,IF(N($AJ13)>0,0,N($AD13))) -> 0 | BA13: =IF($A13="",0,IF($B13="Awaiting Approval",COUNTIF(BA$1:BA12,">0")+1,0)) -> 0 | BB13: =IF($A13="",0,IF(AND($B13="Approved",$AP13<>"Y"),COUNTIF(BB$1:BB12,">0")+1,0)) -> 0 | BC13: =IF($A13="",0,IF(AND($B13="Approved",N($U13)>0,$AQ13<>"Y"),COUNTIF(BC$1:BC12,">0")+1,0)) -> 0 | BD13: =IF($A13="",0,IF(AND($AR13<>"",N($AR13)<TODAY(),$AS13="",$B13<>"Closed",$B13<>"Cancelled",$B13<>"Denied"),COUNTIF(BD$1:BD12,">0")+1,0)) -> 0 | BE13: =IF($A13="",0,IF(AND($AT13<>"",N($AT13)<=TODAY()+7,$AU13="",$B13<>"Denied",$B13<>"Cancelled",$B13<>"Closed"),COUNTIF(BE$1:BE12,">0")+1,0)) -> 0
W14: =IF($A14="","",N($U14)*N($V14)) | AA14: =IF($A14="","",IF($X14="POV",N($Y14)*MileageRate,0)+N($Z14)) | AB14: =IF(OR($A14="",$P14="",$R14="",$Q14="",$S14=""),"",IF($R14=$P14,($Q14<=T_DepBfast)*($S14>=T_RetBfast)*PD_Bfast+($Q14<=T_DepLunch)*($S14>=T_RetLunch)*PD_Lunch+($Q14<=T_DepDinner)*($S14>=T_RetDinner)*PD_Dinner+PD_Incid,($Q14<=T_DepBfast)*PD_Bfast+($Q14<=T_DepLunch)*PD_Lunch+($Q14<=T_DepDinner)*PD_Dinner+($S14>=T_RetBfast)*PD_Bfast+($S14>=T_RetLunch)*PD_Lunch+($S14>=T_RetDinner)*PD_Dinner+MAX($R14-$P14-1,0)*(PD_Bfast+PD_Lunch+PD_Dinner)+($R14-$P14+1)*PD_Incid)) | AD14: =IF($A14="","",N($T14)+N($W14)+N($AA14)+N($AB14)+N($AC14)) | AJ14: =IF($A14="","",IF(COUNT($AE14:$AI14)=0,"",SUM($AE14:$AI14))) | AM14: =IF(OR($A14="",$AJ14=""),"",$AJ14-N($AK14)-N($AL14)) | AR14: =IF(OR($A14="",$R14=""),"",$R14+ReceiptDays) | AT14: =IF(OR($A14="",$P14=""),"",($P14-FinanceLeadDays)-MOD(($P14-FinanceLeadDays)-DATE(2024,1,2),7)) | AX14: =IF(OR($A14="",$B14="Denied",$B14="Cancelled"),0,N($AD14)) -> 0 | AY14: =IF($A14="",0,N($AJ14)) -> 0 | AZ14: =IF(OR($A14="",$B14="Denied",$B14="Cancelled",$B14="Closed"),0,IF(N($AJ14)>0,0,N($AD14))) -> 0 | BA14: =IF($A14="",0,IF($B14="Awaiting Approval",COUNTIF(BA$1:BA13,">0")+1,0)) -> 0 | BB14: =IF($A14="",0,IF(AND($B14="Approved",$AP14<>"Y"),COUNTIF(BB$1:BB13,">0")+1,0)) -> 0 | BC14: =IF($A14="",0,IF(AND($B14="Approved",N($U14)>0,$AQ14<>"Y"),COUNTIF(BC$1:BC13,">0")+1,0)) -> 0 | BD14: =IF($A14="",0,IF(AND($AR14<>"",N($AR14)<TODAY(),$AS14="",$B14<>"Closed",$B14<>"Cancelled",$B14<>"Denied"),COUNTIF(BD$1:BD13,">0")+1,0)) -> 0 | BE14: =IF($A14="",0,IF(AND($AT14<>"",N($AT14)<=TODAY()+7,$AU14="",$B14<>"Denied",$B14<>"Cancelled",$B14<>"Closed"),COUNTIF(BE$1:BE13,">0")+1,0)) -> 0
W15: =IF($A15="","",N($U15)*N($V15)) | AA15: =IF($A15="","",IF($X15="POV",N($Y15)*MileageRate,0)+N($Z15)) | AB15: =IF(OR($A15="",$P15="",$R15="",$Q15="",$S15=""),"",IF($R15=$P15,($Q15<=T_DepBfast)*($S15>=T_RetBfast)*PD_Bfast+($Q15<=T_DepLunch)*($S15>=T_RetLunch)*PD_Lunch+($Q15<=T_DepDinner)*($S15>=T_RetDinner)*PD_Dinner+PD_Incid,($Q15<=T_DepBfast)*PD_Bfast+($Q15<=T_DepLunch)*PD_Lunch+($Q15<=T_DepDinner)*PD_Dinner+($S15>=T_RetBfast)*PD_Bfast+($S15>=T_RetLunch)*PD_Lunch+($S15>=T_RetDinner)*PD_Dinner+MAX($R15-$P15-1,0)*(PD_Bfast+PD_Lunch+PD_Dinner)+($R15-$P15+1)*PD_Incid)) | AD15: =IF($A15="","",N($T15)+N($W15)+N($AA15)+N($AB15)+N($AC15)) | AJ15: =IF($A15="","",IF(COUNT($AE15:$AI15)=0,"",SUM($AE15:$AI15))) | AM15: =IF(OR($A15="",$AJ15=""),"",$AJ15-N($AK15)-N($AL15)) | AR15: =IF(OR($A15="",$R15=""),"",$R15+ReceiptDays) | AT15: =IF(OR($A15="",$P15=""),"",($P15-FinanceLeadDays)-MOD(($P15-FinanceLeadDays)-DATE(2024,1,2),7)) | AX15: =IF(OR($A15="",$B15="Denied",$B15="Cancelled"),0,N($AD15)) -> 0 | AY15: =IF($A15="",0,N($AJ15)) -> 0 | AZ15: =IF(OR($A15="",$B15="Denied",$B15="Cancelled",$B15="Closed"),0,IF(N($AJ15)>0,0,N($AD15))) -> 0 | BA15: =IF($A15="",0,IF($B15="Awaiting Approval",COUNTIF(BA$1:BA14,">0")+1,0)) -> 0 | BB15: =IF($A15="",0,IF(AND($B15="Approved",$AP15<>"Y"),COUNTIF(BB$1:BB14,">0")+1,0)) -> 0 | BC15: =IF($A15="",0,IF(AND($B15="Approved",N($U15)>0,$AQ15<>"Y"),COUNTIF(BC$1:BC14,">0")+1,0)) -> 0 | BD15: =IF($A15="",0,IF(AND($AR15<>"",N($AR15)<TODAY(),$AS15="",$B15<>"Closed",$B15<>"Cancelled",$B15<>"Denied"),COUNTIF(BD$1:BD14,">0")+1,0)) -> 0 | BE15: =IF($A15="",0,IF(AND($AT15<>"",N($AT15)<=TODAY()+7,$AU15="",$B15<>"Denied",$B15<>"Cancelled",$B15<>"Closed"),COUNTIF(BE$1:BE14,">0")+1,0)) -> 0
W16: =IF($A16="","",N($U16)*N($V16)) | AA16: =IF($A16="","",IF($X16="POV",N($Y16)*MileageRate,0)+N($Z16)) | AB16: =IF(OR($A16="",$P16="",$R16="",$Q16="",$S16=""),"",IF($R16=$P16,($Q16<=T_DepBfast)*($S16>=T_RetBfast)*PD_Bfast+($Q16<=T_DepLunch)*($S16>=T_RetLunch)*PD_Lunch+($Q16<=T_DepDinner)*($S16>=T_RetDinner)*PD_Dinner+PD_Incid,($Q16<=T_DepBfast)*PD_Bfast+($Q16<=T_DepLunch)*PD_Lunch+($Q16<=T_DepDinner)*PD_Dinner+($S16>=T_RetBfast)*PD_Bfast+($S16>=T_RetLunch)*PD_Lunch+($S16>=T_RetDinner)*PD_Dinner+MAX($R16-$P16-1,0)*(PD_Bfast+PD_Lunch+PD_Dinner)+($R16-$P16+1)*PD_Incid)) | AD16: =IF($A16="","",N($T16)+N($W16)+N($AA16)+N($AB16)+N($AC16)) | AJ16: =IF($A16="","",IF(COUNT($AE16:$AI16)=0,"",SUM($AE16:$AI16))) | AM16: =IF(OR($A16="",$AJ16=""),"",$AJ16-N($AK16)-N($AL16)) | AR16: =IF(OR($A16="",$R16=""),"",$R16+ReceiptDays) | AT16: =IF(OR($A16="",$P16=""),"",($P16-FinanceLeadDays)-MOD(($P16-FinanceLeadDays)-DATE(2024,1,2),7)) | AX16: =IF(OR($A16="",$B16="Denied",$B16="Cancelled"),0,N($AD16)) -> 0 | AY16: =IF($A16="",0,N($AJ16)) -> 0 | AZ16: =IF(OR($A16="",$B16="Denied",$B16="Cancelled",$B16="Closed"),0,IF(N($AJ16)>0,0,N($AD16))) -> 0 | BA16: =IF($A16="",0,IF($B16="Awaiting Approval",COUNTIF(BA$1:BA15,">0")+1,0)) -> 0 | BB16: =IF($A16="",0,IF(AND($B16="Approved",$AP16<>"Y"),COUNTIF(BB$1:BB15,">0")+1,0)) -> 0 | BC16: =IF($A16="",0,IF(AND($B16="Approved",N($U16)>0,$AQ16<>"Y"),COUNTIF(BC$1:BC15,">0")+1,0)) -> 0 | BD16: =IF($A16="",0,IF(AND($AR16<>"",N($AR16)<TODAY(),$AS16="",$B16<>"Closed",$B16<>"Cancelled",$B16<>"Denied"),COUNTIF(BD$1:BD15,">0")+1,0)) -> 0 | BE16: =IF($A16="",0,IF(AND($AT16<>"",N($AT16)<=TODAY()+7,$AU16="",$B16<>"Denied",$B16<>"Cancelled",$B16<>"Closed"),COUNTIF(BE$1:BE15,">0")+1,0)) -> 0
W17: =IF($A17="","",N($U17)*N($V17)) | AA17: =IF($A17="","",IF($X17="POV",N($Y17)*MileageRate,0)+N($Z17)) | AB17: =IF(OR($A17="",$P17="",$R17="",$Q17="",$S17=""),"",IF($R17=$P17,($Q17<=T_DepBfast)*($S17>=T_RetBfast)*PD_Bfast+($Q17<=T_DepLunch)*($S17>=T_RetLunch)*PD_Lunch+($Q17<=T_DepDinner)*($S17>=T_RetDinner)*PD_Dinner+PD_Incid,($Q17<=T_DepBfast)*PD_Bfast+($Q17<=T_DepLunch)*PD_Lunch+($Q17<=T_DepDinner)*PD_Dinner+($S17>=T_RetBfast)*PD_Bfast+($S17>=T_RetLunch)*PD_Lunch+($S17>=T_RetDinner)*PD_Dinner+MAX($R17-$P17-1,0)*(PD_Bfast+PD_Lunch+PD_Dinner)+($R17-$P17+1)*PD_Incid)) | AD17: =IF($A17="","",N($T17)+N($W17)+N($AA17)+N($AB17)+N($AC17)) | AJ17: =IF($A17="","",IF(COUNT($AE17:$AI17)=0,"",SUM($AE17:$AI17))) | AM17: =IF(OR($A17="",$AJ17=""),"",$AJ17-N($AK17)-N($AL17)) | AR17: =IF(OR($A17="",$R17=""),"",$R17+ReceiptDays) | AT17: =IF(OR($A17="",$P17=""),"",($P17-FinanceLeadDays)-MOD(($P17-FinanceLeadDays)-DATE(2024,1,2),7)) | AX17: =IF(OR($A17="",$B17="Denied",$B17="Cancelled"),0,N($AD17)) -> 0 | AY17: =IF($A17="",0,N($AJ17)) -> 0 | AZ17: =IF(OR($A17="",$B17="Denied",$B17="Cancelled",$B17="Closed"),0,IF(N($AJ17)>0,0,N($AD17))) -> 0 | BA17: =IF($A17="",0,IF($B17="Awaiting Approval",COUNTIF(BA$1:BA16,">0")+1,0)) -> 0 | BB17: =IF($A17="",0,IF(AND($B17="Approved",$AP17<>"Y"),COUNTIF(BB$1:BB16,">0")+1,0)) -> 0 | BC17: =IF($A17="",0,IF(AND($B17="Approved",N($U17)>0,$AQ17<>"Y"),COUNTIF(BC$1:BC16,">0")+1,0)) -> 0 | BD17: =IF($A17="",0,IF(AND($AR17<>"",N($AR17)<TODAY(),$AS17="",$B17<>"Closed",$B17<>"Cancelled",$B17<>"Denied"),COUNTIF(BD$1:BD16,">0")+1,0)) -> 0 | BE17: =IF($A17="",0,IF(AND($AT17<>"",N($AT17)<=TODAY()+7,$AU17="",$B17<>"Denied",$B17<>"Cancelled",$B17<>"Closed"),COUNTIF(BE$1:BE16,">0")+1,0)) -> 0
... W251: =IF($A251="","",N($U251)*N($V251)) | AA251: =IF($A251="","",IF($X251="POV",N($Y251)*MileageRate,0)+N($Z251)) | AB251: =IF(OR($A251="",$P251="",$R251="",$Q251="",$S251=""),"",IF($R251=$P251,($Q251<=T_DepBfast)*($S251>=T_RetBfast)*PD_Bfast+($Q251<=T_DepLunch)*($S251>=T_RetLunch)*PD_Lunch+($Q251<=T_DepDinner)*($S251>=T_RetDinner)*PD_Dinner+PD_Incid,($Q251<=T_DepBfast)*PD_Bfast+($Q251<=T_DepLunch)*PD_Lunch+($Q251<=T_DepDinner)*PD_Dinner+($S251>=T_RetBfast)*PD_Bfast+($S251>=T_RetLunch)*PD_Lunch+($S251>=T_RetDinner)*PD_Dinner+MAX($R251-$P251-1,0)*(PD_Bfast+PD_Lunch+PD_Dinner)+($R251-$P251+1)*PD_Incid)) | AD251: =IF($A251="","",N($T251)+N($W251)+N($AA251)+N($AB251)+N($AC251)) | AJ251: =IF($A251="","",IF(COUNT($AE251:$AI251)=0,"",SUM($AE251:$AI251))) | AM251: =IF(OR($A251="",$AJ251=""),"",$AJ251-N($AK251)-N($AL251)) | AR251: =IF(OR($A251="",$R251=""),"",$R251+ReceiptDays) | AT251: =IF(OR($A251="",$P251=""),"",($P251-FinanceLeadDays)-MOD(($P251-FinanceLeadDays)-DATE(2024,1,2),7)) | AX251: =IF(OR($A251="",$B251="Denied",$B251="Cancelled"),0,N($AD251)) -> 0 | AY251: =IF($A251="",0,N($AJ251)) -> 0 | AZ251: =IF(OR($A251="",$B251="Denied",$B251="Cancelled",$B251="Closed"),0,IF(N($AJ251)>0,0,N($AD251))) -> 0 | BA251: =IF($A251="",0,IF($B251="Awaiting Approval",COUNTIF(BA$1:BA250,">0")+1,0)) -> 0 | BB251: =IF($A251="",0,IF(AND($B251="Approved",$AP251<>"Y"),COUNTIF(BB$1:BB250,">0")+1,0)) -> 0 | BC251: =IF($A251="",0,IF(AND($B251="Approved",N($U251)>0,$AQ251<>"Y"),COUNTIF(BC$1:BC250,">0")+1,0)) -> 0 | BD251: =IF($A251="",0,IF(AND($AR251<>"",N($AR251)<TODAY(),$AS251="",$B251<>"Closed",$B251<>"Cancelled",$B251<>"Denied"),COUNTIF(BD$1:BD250,">0")+1,0)) -> 0 | BE251: =IF($A251="",0,IF(AND($AT251<>"",N($AT251)<=TODAY()+7,$AU251="",$B251<>"Denied",$B251<>"Cancelled",$B251<>"Closed"),COUNTIF(BE$1:BE250,">0")+1,0)) -> 0

Sheet Application
A1: TYLER POLICE DEPARTMENT — TRAINING / TRAVEL APPLICATION
A2: Internal chain-of-command approval. Auto-filled from the Dashboard's ACTIVE RECORD — never type on this sheet.
B5: Tracking # | C5: =IF(ActiveRow=0,"",INDEX(Requests!$A$2:$A$251,ActiveRow)) -> T26-003 | D5: Date Submitted | E5: =IF(ActiveRow=0,"",INDEX(Requests!$AN$2:$AN$251,ActiveRow)) -> 46223
B7: APPLICANT
B8: Name | C8: =IF(ActiveRow=0,"",INDEX(Requests!$C$2:$C$251,ActiveRow)) -> SAMPLE — A. Chen | D8: Rank | E8: =IF(ActiveRow=0,"",INDEX(Requests!$D$2:$D$251,ActiveRow)) -> Corporal
B9: Employee ID | C9: =IF(ActiveRow=0,"",INDEX(Requests!$E$2:$E$251,ActiveRow)) -> 4215 | D9: Division | E9: =IF(ActiveRow=0,"",INDEX(Requests!$F$2:$F$251,ActiveRow)) -> Traffic
B10: Supervisor | C10: =IF(ActiveRow=0,"",INDEX(Requests!$I$2:$I$251,ActiveRow)) -> Sgt. R. Lee | D10: Phone | E10: =IF(ActiveRow=0,"",INDEX(Requests!$H$2:$H$251,ActiveRow)) -> 903-555-0103
B12: COURSE / EVENT
B13: Course | C13: =IF(ActiveRow=0,"",INDEX(Requests!$K$2:$K$251,ActiveRow)) -> Advanced Crash Reconstruction
B14: Provider / Host | C14: =IF(ActiveRow=0,"",INDEX(Requests!$L$2:$L$251,ActiveRow)) -> TEEX | D14: TCOLE # | E14: =IF(ActiveRow=0,"",INDEX(Requests!$BF$2:$BF$251,ActiveRow)) -> 0
B15: Location | C15: =IF(ActiveRow=0,"",INDEX(Requests!$M$2:$M$251,ActiveRow)) -> College Station, TX | D15: Class Dates | E15: =IF(ActiveRow=0,"",TEXT(INDEX(Requests!$N$2:$N$251,ActiveRow),"mm/dd/yy")&" – "&TEXT(INDEX(Requests!$O$2:$O$251,ActiveRow),"mm/dd/yy")) -> 08/24/26 – 08/28/26
B16: Departure | C16: =IF(ActiveRow=0,"",TEXT(INDEX(Requests!$P$2:$P$251,ActiveRow),"mm/dd/yy")&" "&TEXT(INDEX(Requests!$Q$2:$Q$251,ActiveRow),"h:mm AM/PM")) -> 08/23/26 1:00 PM | D16: Return | E16: =IF(ActiveRow=0,"",TEXT(INDEX(Requests!$R$2:$R$251,ActiveRow),"mm/dd/yy")&" "&TEXT(INDEX(Requests!$S$2:$S$251,ActiveRow),"h:mm AM/PM")) -> 08/28/26 6:30 PM
B18: ESTIMATED COST (calculated under city travel policy)
B19: Registration | C19: =IF(ActiveRow=0,"",INDEX(Requests!$T$2:$T$251,ActiveRow)) -> 450
B20: Lodging | C20: =IF(ActiveRow=0,"",INDEX(Requests!$W$2:$W$251,ActiveRow)) -> 645
B21: Travel / Mileage | C21: =IF(ActiveRow=0,"",INDEX(Requests!$AA$2:$AA$251,ActiveRow)) -> 0
B22: Per Diem (M&IE) | C22: =IF(ActiveRow=0,"",INDEX(Requests!$AB$2:$AB$251,ActiveRow)) -> 300
B23: Other | C23: =IF(ActiveRow=0,"",INDEX(Requests!$AC$2:$AC$251,ActiveRow)) -> 35
B24: TOTAL ESTIMATE | C24: =IF(ActiveRow=0,"",INDEX(Requests!$AD$2:$AD$251,ActiveRow)) -> 1430
B26: JUSTIFICATION
B27: =IF(ActiveRow=0,"",INDEX(Requests!$BI$2:$BI$251,ActiveRow)) -> Required for accident-investigator certification.
B31: APPROVALS
B34: Immediate Supervisor / Date | D34: Division Commander / Date
B37: Training Coordinator / Date | D37: Chief of Police / Designee / Date
B39: ="Generated by TPD Training Master — record "&IF(ActiveRow=0,"(none selected)",ActiveTrk)&" — "&TEXT(TODAY(),"mm/dd/yyyy") -> Generated by TPD Training Master — record T26-003 — 08/09/2026

Sheet Pre 2-90
A1: CITY OF TYLER — TRAVEL EXPENSE FORM 2-90 • PRE-TRIP ESTIMATE & AUTHORIZATION
A2: Functional recreation of the Finance form — auto-filled from the ACTIVE RECORD. If Finance issues a new 2-90, replace this sheet per docs/.
B5: Department | C5: ="Police" -> Police | E5: Tracking # | F5: =IF(ActiveRow=0,"",INDEX(Requests!$A$2:$A$251,ActiveRow)) -> T26-003
B6: Employee | C6: =IF(ActiveRow=0,"",INDEX(Requests!$C$2:$C$251,ActiveRow)) -> SAMPLE — A. Chen | E6: Title / Rank | F6: =IF(ActiveRow=0,"",INDEX(Requests!$D$2:$D$251,ActiveRow)) -> Corporal
B7: Destination | C7: =IF(ActiveRow=0,"",INDEX(Requests!$M$2:$M$251,ActiveRow)) -> College Station, TX | E7: Employee ID | F7: =IF(ActiveRow=0,"",INDEX(Requests!$E$2:$E$251,ActiveRow)) -> 4215
B8: Purpose (course/event) | C8: =IF(ActiveRow=0,"",INDEX(Requests!$K$2:$K$251,ActiveRow)) -> Advanced Crash Reconstruction
B9: Departure | C9: =IF(ActiveRow=0,"",TEXT(INDEX(Requests!$P$2:$P$251,ActiveRow),"mm/dd/yy")&" "&TEXT(INDEX(Requests!$Q$2:$Q$251,ActiveRow),"h:mm AM/PM")) -> 08/23/26 1:00 PM | E9: Return | F9: =IF(ActiveRow=0,"",TEXT(INDEX(Requests!$R$2:$R$251,ActiveRow),"mm/dd/yy")&" "&TEXT(INDEX(Requests!$S$2:$S$251,ActiveRow),"h:mm AM/PM")) -> 08/28/26 6:30 PM
B11: EXPENSES (estimated)
B12: Category | C12: Account Code | D12: Estimated
B13: Registration / Tuition | D13: =IF(ActiveRow=0,"",INDEX(Requests!$T$2:$T$251,ActiveRow)) -> 450
B14: Lodging | D14: =IF(ActiveRow=0,"",INDEX(Requests!$W$2:$W$251,ActiveRow)) -> 645
B15: Meals & Incidentals (per diem) | D15: =IF(ActiveRow=0,"",INDEX(Requests!$AB$2:$AB$251,ActiveRow)) -> 300
B16: Transportation | D16: =IF(ActiveRow=0,"",INDEX(Requests!$AA$2:$AA$251,ActiveRow)) -> 0
B17: Other | D17: =IF(ActiveRow=0,"",INDEX(Requests!$AC$2:$AC$251,ActiveRow)) -> 35
B18: TOTAL | D18: =IF(ActiveRow=0,"",SUM(D13:D17)) -> 1430
B20: Advance requested (if any)
B24: Employee / Date | E24: Department Head / Designee / Date
B27: Finance / Date

Sheet Post 2-90
A1: CITY OF TYLER — TRAVEL EXPENSE FORM 2-90 • POST-TRIP RECONCILIATION
A2: Functional recreation of the Finance form — auto-filled from the ACTIVE RECORD. If Finance issues a new 2-90, replace this sheet per docs/.
B5: Department | C5: ="Police" -> Police | E5: Tracking # | F5: =IF(ActiveRow=0,"",INDEX(Requests!$A$2:$A$251,ActiveRow)) -> T26-003
B6: Employee | C6: =IF(ActiveRow=0,"",INDEX(Requests!$C$2:$C$251,ActiveRow)) -> SAMPLE — A. Chen | E6: Title / Rank | F6: =IF(ActiveRow=0,"",INDEX(Requests!$D$2:$D$251,ActiveRow)) -> Corporal
B7: Destination | C7: =IF(ActiveRow=0,"",INDEX(Requests!$M$2:$M$251,ActiveRow)) -> College Station, TX | E7: Employee ID | F7: =IF(ActiveRow=0,"",INDEX(Requests!$E$2:$E$251,ActiveRow)) -> 4215
B8: Purpose (course/event) | C8: =IF(ActiveRow=0,"",INDEX(Requests!$K$2:$K$251,ActiveRow)) -> Advanced Crash Reconstruction
B9: Departure | C9: =IF(ActiveRow=0,"",TEXT(INDEX(Requests!$P$2:$P$251,ActiveRow),"mm/dd/yy")&" "&TEXT(INDEX(Requests!$Q$2:$Q$251,ActiveRow),"h:mm AM/PM")) -> 08/23/26 1:00 PM | E9: Return | F9: =IF(ActiveRow=0,"",TEXT(INDEX(Requests!$R$2:$R$251,ActiveRow),"mm/dd/yy")&" "&TEXT(INDEX(Requests!$S$2:$S$251,ActiveRow),"h:mm AM/PM")) -> 08/28/26 6:30 PM
B11: EXPENSES (estimate vs. actual)
B12: Category | C12: Account Code | D12: Estimated | E12: Actual | F12: Variance
B13: Registration / Tuition | D13: =IF(ActiveRow=0,"",INDEX(Requests!$T$2:$T$251,ActiveRow)) -> 450 | E13: =IF(ActiveRow=0,"",INDEX(Requests!$AE$2:$AE$251,ActiveRow)) -> 0 | F13: =IF(OR($D13="",$E13=""),"",$D13-$E13)
B14: Lodging | D14: =IF(ActiveRow=0,"",INDEX(Requests!$W$2:$W$251,ActiveRow)) -> 645 | E14: =IF(ActiveRow=0,"",INDEX(Requests!$AF$2:$AF$251,ActiveRow)) -> 0 | F14: =IF(OR($D14="",$E14=""),"",$D14-$E14)
B15: Meals & Incidentals (per diem) | D15: =IF(ActiveRow=0,"",INDEX(Requests!$AB$2:$AB$251,ActiveRow)) -> 300 | E15: =IF(ActiveRow=0,"",INDEX(Requests!$AH$2:$AH$251,ActiveRow)) -> 0 | F15: =IF(OR($D15="",$E15=""),"",$D15-$E15)
B16: Transportation | D16: =IF(ActiveRow=0,"",INDEX(Requests!$AA$2:$AA$251,ActiveRow)) -> 0 | E16: =IF(ActiveRow=0,"",INDEX(Requests!$AG$2:$AG$251,ActiveRow)) -> 0 | F16: =IF(OR($D16="",$E16=""),"",$D16-$E16)
B17: Other | D17: =IF(ActiveRow=0,"",INDEX(Requests!$AC$2:$AC$251,ActiveRow)) -> 35 | E17: =IF(ActiveRow=0,"",INDEX(Requests!$AI$2:$AI$251,ActiveRow)) -> 0 | F17: =IF(OR($D17="",$E17=""),"",$D17-$E17)
B18: TOTAL | D18: =IF(ActiveRow=0,"",SUM(D13:D17)) -> 1430 | E18: =IF(ActiveRow=0,"",SUM(E13:E17)) -> 0
B20: Total actual expenses | C20: =IF(ActiveRow=0,"",INDEX(Requests!$AJ$2:$AJ$251,ActiveRow))
B21: Less: paid directly by city | C21: =IF(ActiveRow=0,"",INDEX(Requests!$AK$2:$AK$251,ActiveRow)) -> 0
B22: Less: advance to employee | C22: =IF(ActiveRow=0,"",INDEX(Requests!$AL$2:$AL$251,ActiveRow)) -> 0
B23: BALANCE DUE EMPLOYEE / (CITY) | C23: =IF(ActiveRow=0,"",INDEX(Requests!$AM$2:$AM$251,ActiveRow))
B25: I certify these expenses were incurred on official city business and itemized receipts are attached.
B29: Employee / Date | E29: Department Head / Designee / Date
B32: Finance / Date

Sheet Notification
A1: TPD TRAINING UNIT — ATTENDEE TRAVEL NOTIFICATION
A2: Give this sheet to the traveler. Auto-filled from the ACTIVE RECORD.
B5: To | C5: =IF(ActiveRow=0,"",INDEX(Requests!$C$2:$C$251,ActiveRow)) -> SAMPLE — A. Chen | D5: Tracking # | E5: =IF(ActiveRow=0,"",INDEX(Requests!$A$2:$A$251,ActiveRow)) -> T26-003
B6: From | C6: =CoordName -> Training Coordinator | D6: Date | E6: =TODAY() -> 46243
B8: YOUR TRIP
B9: Course | C9: =IF(ActiveRow=0,"",INDEX(Requests!$K$2:$K$251,ActiveRow)) -> Advanced Crash Reconstruction
B10: Provider | C10: =IF(ActiveRow=0,"",INDEX(Requests!$L$2:$L$251,ActiveRow)) -> TEEX | D10: Location | E10: =IF(ActiveRow=0,"",INDEX(Requests!$M$2:$M$251,ActiveRow)) -> College Station, TX
B11: Class Dates | C11: =IF(ActiveRow=0,"",TEXT(INDEX(Requests!$N$2:$N$251,ActiveRow),"mm/dd/yy")&" – "&TEXT(INDEX(Requests!$O$2:$O$251,ActiveRow),"mm/dd/yy")) -> 08/24/26 – 08/28/26 | D11: Travel Mode | E11: =IF(ActiveRow=0,"",INDEX(Requests!$X$2:$X$251,ActiveRow)) -> City Vehicle
B12: Depart | C12: =IF(ActiveRow=0,"",TEXT(INDEX(Requests!$P$2:$P$251,ActiveRow),"dddd mm/dd")&" at "&TEXT(INDEX(Requests!$Q$2:$Q$251,ActiveRow),"h:mm AM/PM")) -> Sunday 08/23 at 1:00 PM | D12: Return | E12: =IF(ActiveRow=0,"",TEXT(INDEX(Requests!$R$2:$R$251,ActiveRow),"dddd mm/dd")&" at "&TEXT(INDEX(Requests!$S$2:$S$251,ActiveRow),"h:mm AM/PM")) -> Friday 08/28 at 6:30 PM
B14: WHAT IS ARRANGED FOR YOU
B15: Registration | C15: =IF(ActiveRow=0,"",IF(INDEX(Requests!$AP$2:$AP$251,ActiveRow)="Y","PAID — "&TEXT(INDEX(Requests!$T$2:$T$251,ActiveRow),"$#,##0.00"),"Pending")) -> Pending | D15: Hotel | E15: =IF(ActiveRow=0,"",IF(N(INDEX(Requests!$U$2:$U$251,ActiveRow))=0,"None needed",IF(INDEX(Requests!$AQ$2:$AQ$251,ActiveRow)="Y","BOOKED — "&INDEX(Requests!$U$2:$U$251,ActiveRow)&" nights","Pending"))) -> Pending
B17: YOUR MONEY
B18: Per Diem (M&IE) | C18: =IF(ActiveRow=0,"",INDEX(Requests!$AB$2:$AB$251,ActiveRow)) -> 300 | D18: Mileage / travel | E18: =IF(ActiveRow=0,"",INDEX(Requests!$AA$2:$AA$251,ActiveRow)) -> 0
B20: =IF(ActiveRow=0,"","Per diem is calculated from your departure and return times under city travel policy. KEEP EVERY ITEMIZED RECEIPT — turn them in to the Training Unit by "&TEXT(INDEX(Requests!$AR$2:$AR$251,ActiveRow),"dddd, mmmm d")&". Questions: "&CoordName&", "&CoordPhone&".") -> Per diem is calculated from your departure and return times under city travel policy. KEEP EVERY ITEMIZED RECEIPT — turn them in to the Training Unit by Friday, September 4. Questions: Training Coordinator, 903-555-0100.

Sheet Ledger
A1: Tracking # | B1: Month | C1: Officer | D1: Course / Event | E1: Status | F1: Estimated | G1: Actual | H1: Variance (E−A) | I1: Balance Due Traveler | J1: Receipts Rec'd | K1: Sent to Finance | L1: Reconciled?
A2: =IF(Requests!$A2="","",Requests!$A2) -> T26-001 | B2: =IF(OR(Requests!$A2="",Requests!$P2=""),"",TEXT(Requests!$P2,"yyyy-mm")) -> 2026-03 | C2: =IF(Requests!$A2="","",Requests!$C2) -> SAMPLE — J. Doe | D2: =IF(Requests!$A2="","",Requests!$K2) -> Interview & Interrogation | E2: =IF(Requests!$A2="","",Requests!$B2) -> Closed | F2: =IF(Requests!$A2="","",Requests!$AD2) -> 889 | G2: =IF(Requests!$A2="","",Requests!$AJ2) -> 889.07 | H2: =IF(OR(Requests!$A2="",Requests!$AJ2=""),"",Requests!$AD2-Requests!$AJ2) -> -0.07 | I2: =IF(Requests!$A2="","",Requests!$AM2) -> 0 | J2: =IF(OR(Requests!$A2="",Requests!$AS2=""),"",Requests!$AS2) -> 46097 | K2: =IF(OR(Requests!$A2="",Requests!$AU2=""),"",Requests!$AU2) -> 46098 | L2: =IF(Requests!$A2="","",IF(AND(Requests!$AJ2<>"",Requests!$AS2<>"",Requests!$AU2<>""),"Yes","Open")) -> Yes
A3: =IF(Requests!$A3="","",Requests!$A3) -> T26-002 | B3: =IF(OR(Requests!$A3="",Requests!$P3=""),"",TEXT(Requests!$P3,"yyyy-mm")) -> 2026-07 | C3: =IF(Requests!$A3="","",Requests!$C3) -> SAMPLE — M. Rivera | D3: =IF(Requests!$A3="","",Requests!$K3) -> Homicide Investigation | E3: =IF(Requests!$A3="","",Requests!$B3) -> Travel Complete | F3: =IF(Requests!$A3="","",Requests!$AD3) -> 802 | G3: =IF(Requests!$A3="","",Requests!$AJ3) | H3: =IF(OR(Requests!$A3="",Requests!$AJ3=""),"",Requests!$AD3-Requests!$AJ3) | I3: =IF(Requests!$A3="","",Requests!$AM3) | J3: =IF(OR(Requests!$A3="",Requests!$AS3=""),"",Requests!$AS3) | K3: =IF(OR(Requests!$A3="",Requests!$AU3=""),"",Requests!$AU3) | L3: =IF(Requests!$A3="","",IF(AND(Requests!$AJ3<>"",Requests!$AS3<>"",Requests!$AU3<>""),"Yes","Open")) -> Open
A4: =IF(Requests!$A4="","",Requests!$A4) -> T26-003 | B4: =IF(OR(Requests!$A4="",Requests!$P4=""),"",TEXT(Requests!$P4,"yyyy-mm")) -> 2026-08 | C4: =IF(Requests!$A4="","",Requests!$C4) -> SAMPLE — A. Chen | D4: =IF(Requests!$A4="","",Requests!$K4) -> Advanced Crash Reconstruction | E4: =IF(Requests!$A4="","",Requests!$B4) -> Approved | F4: =IF(Requests!$A4="","",Requests!$AD4) -> 1430 | G4: =IF(Requests!$A4="","",Requests!$AJ4) | H4: =IF(OR(Requests!$A4="",Requests!$AJ4=""),"",Requests!$AD4-Requests!$AJ4) | I4: =IF(Requests!$A4="","",Requests!$AM4) | J4: =IF(OR(Requests!$A4="",Requests!$AS4=""),"",Requests!$AS4) | K4: =IF(OR(Requests!$A4="",Requests!$AU4=""),"",Requests!$AU4) | L4: =IF(Requests!$A4="","",IF(AND(Requests!$AJ4<>"",Requests!$AS4<>"",Requests!$AU4<>""),"Yes","Open")) -> Open
A5: =IF(Requests!$A5="","",Requests!$A5) -> T26-004 | B5: =IF(OR(Requests!$A5="",Requests!$P5=""),"",TEXT(Requests!$P5,"yyyy-mm")) -> 2026-09 | C5: =IF(Requests!$A5="","",Requests!$C5) -> SAMPLE — T. Okafor | D5: =IF(Requests!$A5="","",Requests!$K5) -> Crisis Intervention Training | E5: =IF(Requests!$A5="","",Requests!$B5) -> Awaiting Approval | F5: =IF(Requests!$A5="","",Requests!$AD5) -> 369 | G5: =IF(Requests!$A5="","",Requests!$AJ5) | H5: =IF(OR(Requests!$A5="",Requests!$AJ5=""),"",Requests!$AD5-Requests!$AJ5) | I5: =IF(Requests!$A5="","",Requests!$AM5) | J5: =IF(OR(Requests!$A5="",Requests!$AS5=""),"",Requests!$AS5) | K5: =IF(OR(Requests!$A5="",Requests!$AU5=""),"",Requests!$AU5) | L5: =IF(Requests!$A5="","",IF(AND(Requests!$AJ5<>"",Requests!$AS5<>"",Requests!$AU5<>""),"Yes","Open")) -> Open
